Workbook

Sheet vtx_bysourcelamb
A1: Row Labels | B1: Row Labels | C1: Dairy | D1: Environment | E1: Lamb | F1: Flour | G1: Meat | H1: Nuts/Seeds | I1: Other | J1: Vegetable | K1: (blank) | L1: Grand Total | Q1: Dairy | R1: Environment | S1: Lamb | T1: Flour | U1: Meat | V1: Nuts/Seeds | W1: Other | X1: Vegetable | AA1: Row Labels | AB1: Dairy | AC1: Flour | AD1: Lamb | AE1: Meat | AF1: Nuts/Seeds | AG1: Other | AH1: Vegetable
A2: aggR | B2: aggR | I2: 3 | L2: 3 | P2: vtx1a | Q2: =SUMIF($B$2:$B$44,CONCATENATE("*",$P$2,"*"),C2:C44) -> 8 | R2: =SUMIF($B$2:$B$44,CONCATENATE("*",$P$2,"*"),D2:D44) -> 3 | S2: =SUMIF($B$2:$B$44,CONCATENATE("*",$P$2,"*"),E2:E44) -> 8 | T2: =SUMIF($B$2:$B$44,CONCATENATE("*",$P$2,"*"),F2:F44) -> 5 | U2: =SUMIF($B$2:$B$44,CONCATENATE("*",$P$2,"*"),G2:G44) -> 102 | V2: =SUMIF($B$2:$B$44,CONCATENATE("*",$P$2,"*"),H2:H44) -> 4 | W2: =SUMIF($B$2:$B$44,CONCATENATE("*",$P$2,"*"),I2:I44) -> 28 | X2: =SUMIF($B$2:$B$44,CONCATENATE("*",$P$2,"*"),J2:J44) -> 2 | AA2: aggR | AG2: 3
A3: eae | B3: eae | I3: 1 | L3: 1 | P3: vtx2a | Q3: =SUMIF($B$2:$B$44,CONCATENATE("*",$P$3,"*"),C2:C44) -> 10 | R3: =SUMIF($B$2:$B$44,CONCATENATE("*",$P$3,"*"),D2:D44) -> 2 | S3: =SUMIF($B$2:$B$44,CONCATENATE("*",$P$3,"*"),E2:E44) -> 0 | T3: =SUMIF($B$2:$B$44,CONCATENATE("*",$P$3,"*"),F2:F44) -> 23 | U3: =SUMIF($B$2:$B$44,CONCATENATE("*",$P$3,"*"),G2:G44) -> 76 | V3: =SUMIF($B$2:$B$44,CONCATENATE("*",$P$3,"*"),H2:H44) -> 14 | W3: =SUMIF($B$2:$B$44,CONCATENATE("*",$P$3,"*"),I2:I44) -> 25 | X3: =SUMIF($B$2:$B$44,CONCATENATE("*",$P$3,"*"),J2:J44) -> 4 | AA3: eae | AG3: 1
A4: ND | B4: ND | G4: 1 | I4: 5 | L4: 8 | P4: vtx2d | Q4: =SUMIF($B$2:$B$44,CONCATENATE("*",$P$4,"*"),C2:C44) -> 3 | R4: =SUMIF($B$2:$B$44,CONCATENATE("*",$P$4,"*"),D2:D44) -> 0 | S4: =SUMIF($B$2:$B$44,CONCATENATE("*",$P$4,"*"),E2:E44) -> 0 | T4: =SUMIF($B$2:$B$44,CONCATENATE("*",$P$4,"*"),F2:F44) -> 0 | U4: =SUMIF($B$2:$B$44,CONCATENATE("*",$P$4,"*"),G2:G44) -> 16 | V4: =SUMIF($B$2:$B$44,CONCATENATE("*",$P$4,"*"),H2:H44) -> 0 | W4: =SUMIF($B$2:$B$44,CONCATENATE("*",$P$4,"*"),I2:I44) -> 9 | X4: =SUMIF($B$2:$B$44,CONCATENATE("*",$P$4,"*"),J2:J44) -> 0 | AA4: ND | AE4: 1 | AG4: 7
A5: stx1a, eae | B5: vtx1a, eae | I5: 11 | L5: 11 | P5: vtx2c | Q5: =SUMIF($B$2:$B$44,CONCATENATE("*",$P$5,"*"),C2:C44) -> 0 | R5: =SUMIF($B$2:$B$44,CONCATENATE("*",$P$5,"*"),D2:D44) -> 7 | S5: =SUMIF($B$2:$B$44,CONCATENATE("*",$P$5,"*"),E2:E44) -> 0 | T5: =SUMIF($B$2:$B$44,CONCATENATE("*",$P$5,"*"),F2:F44) -> 1 | U5: =SUMIF($B$2:$B$44,CONCATENATE("*",$P$5,"*"),G2:G44) -> 40 | V5: =SUMIF($B$2:$B$44,CONCATENATE("*",$P$5,"*"),H2:H44) -> 3 | W5: =SUMIF($B$2:$B$44,CONCATENATE("*",$P$5,"*"),I2:I44) -> 6 | X5: =SUMIF($B$2:$B$44,CONCATENATE("*",$P$5,"*"),J2:J44) -> 0 | AA5: stx1a, eae | AG5: 11
A6: stx1a, stx2a | B6: vtx1a, vtx2a | I6: 1 | L6: 1 | P6: vtx1c | Q6: =SUMIF($B$2:$B$44,CONCATENATE("*",$P$6,"*"),C2:C44) -> 0 | R6: =SUMIF($B$2:$B$44,CONCATENATE("*",$P$6,"*"),D2:D44) -> 0 | S6: =SUMIF($B$2:$B$44,CONCATENATE("*",$P$6,"*"),E2:E44) -> 28 | T6: =SUMIF($B$2:$B$44,CONCATENATE("*",$P$6,"*"),F2:F44) -> 1 | U6: =SUMIF($B$2:$B$44,CONCATENATE("*",$P$6,"*"),G2:G44) -> 42 | V6: =SUMIF($B$2:$B$44,CONCATENATE("*",$P$6,"*"),H2:H44) -> 0 | W6: =SUMIF($B$2:$B$44,CONCATENATE("*",$P$6,"*"),I2:I44) -> 7 | X6: =SUMIF($B$2:$B$44,CONCATENATE("*",$P$6,"*"),J2:J44) -> 0 | AA6: stx1a, stx2a | AG6: 1
A7: stx1a, stx2a, eae | B7: vtx1a, vtx2a, eae | I7: 4 | L7: 4 | P7: vtx2b | Q7: =SUMIF($B$2:$B$44,CONCATENATE("*",$P$7,"*"),C2:C44) -> 0 | R7: =SUMIF($B$2:$B$44,CONCATENATE("*",$P$7,"*"),D2:D44) -> 0 | S7: =SUMIF($B$2:$B$44,CONCATENATE("*",$P$7,"*"),E2:E44) -> 23 | T7: =SUMIF($B$2:$B$44,CONCATENATE("*",$P$7,"*"),F2:F44) -> 0 | U7: =SUMIF($B$2:$B$44,CONCATENATE("*",$P$7,"*"),G2:G44) -> 61 | V7: =SUMIF($B$2:$B$44,CONCATENATE("*",$P$7,"*"),H2:H44) -> 0 | W7: =SUMIF($B$2:$B$44,CONCATENATE("*",$P$7,"*"),I2:I44) -> 10 | X7: =SUMIF($B$2:$B$44,CONCATENATE("*",$P$7,"*"),J2:J44) -> 0 | AA7: stx1a, stx2a, eae | AG7: 4
A8: stx1a, stx2c,eae | B8: vtx1a, vtx2c,eae | I8: 1 | L8: 1 | P8: vtx2k | Q8: =SUMIF($B$2:$B$44,CONCATENATE("*",$P$8,"*"),C2:C44) -> 0 | R8: =SUMIF($B$2:$B$44,CONCATENATE("*",$P$8,"*"),D2:D44) -> 0 | S8: =SUMIF($B$2:$B$44,CONCATENATE("*",$P$8,"*"),E2:E44) -> 0 | T8: =SUMIF($B$2:$B$44,CONCATENATE("*",$P$8,"*"),F2:F44) -> 0 | U8: =SUMIF($B$2:$B$44,CONCATENATE("*",$P$8,"*"),G2:G44) -> 1 | V8: =SUMIF($B$2:$B$44,CONCATENATE("*",$P$8,"*"),H2:H44) -> 0 | W8: =SUMIF($B$2:$B$44,CONCATENATE("*",$P$8,"*"),I2:I44) -> 0 | X8: =SUMIF($B$2:$B$44,CONCATENATE("*",$P$8,"*"),J2:J44) -> 0 | AA8: stx1a, stx2c,eae | AG8: 1
A9: stx1d | B9: vtx1d | I9: 1 | L9: 1 | P9: vtx2e | Q9: =SUMIF($B$2:$B$44,CONCATENATE("*",$P$9,"*"),C2:C44) -> 0 | R9: =SUMIF($B$2:$B$44,CONCATENATE("*",$P$9,"*"),D2:D44) -> 0 | S9: =SUMIF($B$2:$B$44,CONCATENATE("*",$P$9,"*"),E2:E44) -> 1 | T9: =SUMIF($B$2:$B$44,CONCATENATE("*",$P$9,"*"),F2:F44) -> 0 | U9: =SUMIF($B$2:$B$44,CONCATENATE("*",$P$9,"*"),G2:G44) -> 7 | V9: =SUMIF($B$2:$B$44,CONCATENATE("*",$P$9,"*"),H2:H44) -> 0 | W9: =SUMIF($B$2:$B$44,CONCATENATE("*",$P$9,"*"),I2:I44) -> 3 | X9: =SUMIF($B$2:$B$44,CONCATENATE("*",$P$9,"*"),J2:J44) -> 0 | AA9: stx1d | AG9: 1
A10: stx2a, aggR | B10: vtx2a, aggR | I10: 1 | L10: 1 | P10: vtx2g | Q10: =SUMIF($B$2:$B$44,CONCATENATE("*",$P$10,"*"),C2:C44) -> 0 | R10: =SUMIF($B$2:$B$44,CONCATENATE("*",$P$10,"*"),D2:D44) -> 0 | S10: =SUMIF($B$2:$B$44,CONCATENATE("*",$P$10,"*"),E2:E44) -> 0 | T10: =SUMIF($B$2:$B$44,CONCATENATE("*",$P$10,"*"),F2:F44) -> 0 | U10: =SUMIF($B$2:$B$44,CONCATENATE("*",$P$10,"*"),G2:G44) -> 2 | V10: =SUMIF($B$2:$B$44,CONCATENATE("*",$P$10,"*"),H2:H44) -> 0 | W10: =SUMIF($B$2:$B$44,CONCATENATE("*",$P$10,"*"),I2:I44) -> 2 | X10: =SUMIF($B$2:$B$44,CONCATENATE("*",$P$10,"*"),J2:J44) -> 0 | AA10: stx2a, aggR | AG10: 1
A11: stx2a, eae | B11: vtx2a, eae | I11: 2 | L11: 2 | P11: vtx2i | Q11: =SUMIF($B$2:$B$44,CONCATENATE("*",$P$11,"*"),C2:C44) -> 0 | R11: =SUMIF($B$2:$B$44,CONCATENATE("*",$P$11,"*"),D2:D44) -> 0 | S11: =SUMIF($B$2:$B$44,CONCATENATE("*",$P$11,"*"),E2:E44) -> 12 | T11: =SUMIF($B$2:$B$44,CONCATENATE("*",$P$11,"*"),F2:F44) -> 0 | U11: =SUMIF($B$2:$B$44,CONCATENATE("*",$P$11,"*"),G2:G44) -> 0 | V11: =SUMIF($B$2:$B$44,CONCATENATE("*",$P$11,"*"),H2:H44) -> 0 | W11: =SUMIF($B$2:$B$44,CONCATENATE("*",$P$11,"*"),I2:I44) -> 0 | X11: =SUMIF($B$2:$B$44,CONCATENATE("*",$P$11,"*"),J2:J44) -> 0 | AA11: stx2a, eae | AG11: 2
A12: stx2a, stx2d | B12: vtx2a, vtx2d | I12: 1 | L12: 1 | P12: vtx1d | Q12: =SUMIF($B$2:$B$44,CONCATENATE("*",$P$12,"*"),C2:C44) -> 0 | R12: =SUMIF($B$2:$B$44,CONCATENATE("*",$P$12,"*"),D2:D44) -> 0 | S12: =SUMIF($B$2:$B$44,CONCATENATE("*",$P$12,"*"),E2:E44) -> 0 | T12: =SUMIF($B$2:$B$44,CONCATENATE("*",$P$12,"*"),F2:F44) -> 0 | U12: =SUMIF($B$2:$B$44,CONCATENATE("*",$P$12,"*"),G2:G44) -> 0 | V12: =SUMIF($B$2:$B$44,CONCATENATE("*",$P$12,"*"),H2:H44) -> 1 | W12: =SUMIF($B$2:$B$44,CONCATENATE("*",$P$12,"*"),I2:I44) -> 5 | X12: =SUMIF($B$2:$B$44,CONCATENATE("*",$P$12,"*"),J2:J44) -> 0 | AA12: stx2a, stx2d | AG12: 1
A13: stx2c,eae | B13: vtx2c,eae | I13: 1 | L13: 1 | P13: vtx2f | Q13: =SUMIF($B$2:$B$44,CONCATENATE("*",$P$13,"*"),C2:C44) -> 0 | R13: =SUMIF($B$2:$B$44,CONCATENATE("*",$P$13,"*"),D2:D44) -> 0 | S13: =SUMIF($B$2:$B$44,CONCATENATE("*",$P$13,"*"),E2:E44) -> 0 | T13: =SUMIF($B$2:$B$44,CONCATENATE("*",$P$13,"*"),F2:F44) -> 0 | U13: =SUMIF($B$2:$B$44,CONCATENATE("*",$P$13,"*"),G2:G44) -> 0 | V13: =SUMIF($B$2:$B$44,CONCATENATE("*",$P$13,"*"),H2:H44) -> 0 | W13: =SUMIF($B$2:$B$44,CONCATENATE("*",$P$13,"*"),I2:I44) -> 5 | X13: =SUMIF($B$2:$B$44,CONCATENATE("*",$P$13,"*"),J2:J44) -> 0 | AA13: stx2c,eae | AG13: 1
A14: stx2h | B14: vtx2h | J14: 1 | L14: 1 | AA14: stx2h | AH14: 1
A15: vtx1a | B15: vtx1a | F15: 4 | G15: 37 | I15: 8 | L15: 51 | AA15: vtx1a | AC15: 5 | AE15: 37 | AG15: 9
A16: vtx1a,vtx2b | B16: vtx1a,vtx2b | G16: 1 | L16: 1 | AA16: vtx1a,vtx2b | AE16: 1
A17: vtx1a,vtx2c | B17: vtx1a,vtx2c | G17: 1 | L17: 1 | AA17: vtx1a,vtx2c | AE17: 1
A18: vtx1a;vtx1c;vtx2b | B18: vtx1a;vtx1c;vtx2b | G18: 1 | L18: 1 | AA18: vtx1a;vtx1c;vtx2b | AE18: 1
A19: vtx1a;vtx2a | B19: vtx1a;vtx2a | C19: 8 | D19: 2 | F19: 1 | G19: 40 | H19: 4 | I19: 3 | J19: 2 | L19: 115 | AA19: vtx1a;vtx2a | AC19: 9 | AE19: 40 | AF19: 14 | AG19: 50 | AH19: 2
A20: vtx1a;vtx2a (interrupted) | B20: vtx1a;vtx2a (interrupted) | G20: 1 | L20: 1 | AA20: vtx1a;vtx2a (interrupted) | AE20: 1
A21: vtx1a;vtx2b | B21: vtx1a;vtx2b | E21: 8 | G21: 17 | L21: 26 | AA21: vtx1a;vtx2b | AD21: 8 | AE21: 17 | AG21: 1
A22: vtx1a;vtx2c | B22: vtx1a;vtx2c | D22: 1 | G22: 2 | L22: 13 | AA22: vtx1a;vtx2c | AC22: 1 | AE22: 2 | AG22: 10
A23: vtx1a;vtx2d | B23: vtx1a;vtx2d | G23: 2 | L23: 2 | AA23: vtx1a;vtx2d | AE23: 2
A24: vtx1c | B24: vtx1c | E24: 13 | F24: 1 | G24: 15 | I24: 2 | L24: 38 | AA24: vtx1c | AB24: 2 | AD24: 13 | AE24: 15 | AG24: 8
A25: vtx1c,vtx2b | B25: vtx1c,vtx2b | G25: 2 | L25: 2 | AA25: vtx1c,vtx2b | AE25: 2
A26: vtx1c;vtx2a | B26: vtx1c;vtx2a | I26: 1 | L26: 1 | AA26: vtx1c;vtx2a | AG26: 1
A27: vtx1c;vtx2a;vtx2b | B27: vtx1c;vtx2a;vtx2b | G27: 1 | L27: 1 | AA27: vtx1c;vtx2a;vtx2b | AE27: 1
A28: vtx1c;vtx2b | B28: vtx1c;vtx2b | E28: 15 | G28: 23 | I28: 4 | L28: 46 | AA28: vtx1c;vtx2b | AD28: 15 | AE28: 23 | AG28: 8
A29: vtx1d | B29: vtx1d | H29: 1 | I29: 4 | L29: 5 | AA29: vtx1d | AF29: 1 | AG29: 4
A30: vtx2a | B30: vtx2a | C30: 2 | F30: 22 | G30: 33 | H30: 10 | I30: 11 | J30: 2 | L30: 86 | AA30: vtx2a | AB30: 2 | AC30: 19 | AE30: 33 | AF30: 9 | AG30: 19 | AH30: 4
A31: vtx2a;vtx2c | B31: vtx2a;vtx2c | I31: 1 | L31: 1 | AA31: vtx2a;vtx2c | AG31: 1
A32: vtx2a;vtx2k | B32: vtx2a;vtx2k | G32: 1 | L32: 1 | AA32: vtx2a;vtx2k | AE32: 1
A33: vtx2b | B33: vtx2b | G33: 12 | I33: 5 | L33: 17 | AA33: vtx2b | AE33: 12 | AG33: 5
A34: vtx2b;vtx2c | B34: vtx2b;vtx2c | G34: 2 | L34: 2 | AA34: vtx2b;vtx2c | AE34: 2
A35: vtx2b;vtx2c;vtx2d | B35: vtx2b;vtx2c;vtx2d | I35: 1 | L35: 1 | AA35: vtx2b;vtx2c;vtx2d | AG35: 1
A36: vtx2b;vtx2d | B36: vtx2b;vtx2d | G36: 2 | L36: 2 | AA36: vtx2b;vtx2d | AE36: 2
A37: vtx2c | B37: vtx2c | D37: 6 | F37: 1 | G37: 35 | H37: 3 | I37: 2 | L37: 50 | AA37: vtx2c | AC37: 5 | AE37: 35 | AF37: 4 | AG37: 6
A38: vtx2d | B38: vtx2d | C38: 3 | G38: 12 | I38: 7 | L38: 20 | AA38: vtx2d | AE38: 12 | AG38: 8
A39: vtx2e | B39: vtx2e | E39: 1 | G39: 7 | I39: 3 | L39: 11 | AA39: vtx2e | AD39: 1 | AE39: 7 | AG39: 3
A40: vtx2f | B40: vtx2f | I40: 5 | L40: 5 | AA40: vtx2f | AG40: 5
...

Sheet vtx_bysource
A1: Row Labels | B1: Dairy | C1: Environment | D1: Flour | E1: Meat | F1: Nuts/Seeds | G1: Other | H1: Vegetable | J1: countifs (to count number of rows | K1: Dairy | L1: Environment | M1: Flour | N1: Meat | O1: Lamb | P1: Nuts/Seeds | Q1: Other | R1: Vegetable | S1: TOTAL | U1: Protein Allele | V1: Dairy | W1: Environment | X1: Flour | Y1: Meat | Z1: Nuts/Seeds | AA1: Other | AB1: Vegetable
A2: ND | E2: 4 | J2: Stx1a | K2: =COUNTIFS(alldata_newdb!Q:Q, CONCATENATE("*",J2,"*"), alldata_newdb!L:L, "Dairy") -> 8 | L2: =COUNTIFS(alldata_newdb!Q:Q, CONCATENATE("*",J2,"*"), alldata_newdb!L:L, "Environment") -> 3 | M2: =COUNTIFS(alldata_newdb!Q:Q, CONCATENATE("*",J2,"*"), alldata_newdb!L:L, "Flour") -> 5 | N2: =COUNTIFS(alldata_newdb!Q:Q, CONCATENATE("*",J2,"*"), alldata_newdb!L:L, "Meat") -> 195 | O2: =COUNTIFS(alldata_newdb!Q:Q, CONCATENATE("*",J2,"*"), alldata_newdb!L:L, "Lamb") -> 8 | P2: =COUNTIFS(alldata_newdb!Q:Q, CONCATENATE("*",J2,"*"), alldata_newdb!L:L, "Nuts/Seeds") -> 4 | Q2: =COUNTIFS(alldata_newdb!Q:Q, CONCATENATE("*",J2,"*"), alldata_newdb!L:L, "Other") -> 20 | R2: =COUNTIFS(alldata_newdb!Q:Q, CONCATENATE("*",J2,"*"), alldata_newdb!L:L, "Vegetable") -> 2 | S2: =SUM(K2:R2) -> 245 | U2: Stx1a | V2: =SUMIF($A$2:$A$99,CONCATENATE("*",U2,"*"),$B$2:$B$99) -> 8 | W2: =SUMIF($A$2:$A$99,CONCATENATE("*",U2,"*"),$C$2:$C$99) -> 3 | X2: =SUMIF($A$2:$A$99,CONCATENATE("*",U2,"*"),$D$2:$D$99) -> 5 | Y2: =SUMIF($A$2:$A$99,CONCATENATE("*",U2,"*"),$E$2:$E$99) -> 203 | Z2: =SUMIF($A$2:$A$99,CONCATENATE("*",U2,"*"),$F$2:$F$99) -> 4 | AA2: =SUMIF($A$2:$A$99,CONCATENATE("*",U2,"*"),$G$2:$G$99) -> 20 | AB2: =SUMIF($A$2:$A$99,CONCATENATE("*",U2,"*"),$H$2:$H$99) -> 2
A3: StxOp1036_Stx1c_12 | D3: 1 | E3: 21 | G3: 3 | J3: Stx2a | K3: =COUNTIFS(alldata_newdb!Q:Q, CONCATENATE("*",J3,"*"), alldata_newdb!L:L, "Dairy") -> 10 | L3: =COUNTIFS(alldata_newdb!Q:Q, CONCATENATE("*",J3,"*"), alldata_newdb!L:L, "Environment") -> 2 | M3: =COUNTIFS(alldata_newdb!Q:Q, CONCATENATE("*",J3,"*"), alldata_newdb!L:L, "Flour") -> 23 | N3: =COUNTIFS(alldata_newdb!Q:Q, CONCATENATE("*",J3,"*"), alldata_newdb!L:L, "Meat") -> 175 | O3: =COUNTIFS(alldata_newdb!Q:Q, CONCATENATE("*",J3,"*"), alldata_newdb!L:L, "Lamb") -> 0 | P3: =COUNTIFS(alldata_newdb!Q:Q, CONCATENATE("*",J3,"*"), alldata_newdb!L:L, "Nuts/Seeds") -> 14 | Q3: =COUNTIFS(alldata_newdb!Q:Q, CONCATENATE("*",J3,"*"), alldata_newdb!L:L, "Other") -> 10 | R3: =COUNTIFS(alldata_newdb!Q:Q, CONCATENATE("*",J3,"*"), alldata_newdb!L:L, "Vegetable") -> 4 | S3: =SUM(K3:R3) -> 238 | U3: Stx2a | V3: =SUMIF($A$2:$A$99,CONCATENATE("*",U3,"*"),$B$2:$B$99) -> 10 | W3: =SUMIF($A$2:$A$99,CONCATENATE("*",U3,"*"),$C$2:$C$99) -> 2 | X3: =SUMIF($A$2:$A$99,CONCATENATE("*",U3,"*"),$D$2:$D$99) -> 23 | Y3: =SUMIF($A$2:$A$99,CONCATENATE("*",U3,"*"),$E$2:$E$99) -> 175 | Z3: =SUMIF($A$2:$A$99,CONCATENATE("*",U3,"*"),$F$2:$F$99) -> 14 | AA3: =SUMIF($A$2:$A$99,CONCATENATE("*",U3,"*"),$G$2:$G$99) -> 10 | AB3: =SUMIF($A$2:$A$99,CONCATENATE("*",U3,"*"),$H$2:$H$99) -> 4
A4: StxOp1037_Stx1c_26 | E4: 2 | G4: 1 | J4: Stx2d | K4: =COUNTIFS(alldata_newdb!Q:Q, CONCATENATE("*",J4,"*"), alldata_newdb!L:L, "Dairy") -> 3 | L4: =COUNTIFS(alldata_newdb!Q:Q, CONCATENATE("*",J4,"*"), alldata_newdb!L:L, "Environment") -> 0 | M4: =COUNTIFS(alldata_newdb!Q:Q, CONCATENATE("*",J4,"*"), alldata_newdb!L:L, "Flour") -> 0 | N4: =COUNTIFS(alldata_newdb!Q:Q, CONCATENATE("*",J4,"*"), alldata_newdb!L:L, "Meat") -> 15 | O4: =COUNTIFS(alldata_newdb!Q:Q, CONCATENATE("*",J4,"*"), alldata_newdb!L:L, "Lamb") -> 0 | P4: =COUNTIFS(alldata_newdb!Q:Q, CONCATENATE("*",J4,"*"), alldata_newdb!L:L, "Nuts/Seeds") -> 0 | Q4: =COUNTIFS(alldata_newdb!Q:Q, CONCATENATE("*",J4,"*"), alldata_newdb!L:L, "Other") -> 2 | R4: =COUNTIFS(alldata_newdb!Q:Q, CONCATENATE("*",J4,"*"), alldata_newdb!L:L, "Vegetable") -> 0 | S4: =SUM(K4:R4) -> 20 | U4: Stx2d | V4: =SUMIF($A$2:$A$99,CONCATENATE("*",U4,"*"),$B$2:$B$99) -> 3 | W4: =SUMIF($A$2:$A$99,CONCATENATE("*",U4,"*"),$C$2:$C$99) -> 0 | X4: =SUMIF($A$2:$A$99,CONCATENATE("*",U4,"*"),$D$2:$D$99) -> 0 | Y4: =SUMIF($A$2:$A$99,CONCATENATE("*",U4,"*"),$E$2:$E$99) -> 15 | Z4: =SUMIF($A$2:$A$99,CONCATENATE("*",U4,"*"),$F$2:$F$99) -> 0 | AA4: =SUMIF($A$2:$A$99,CONCATENATE("*",U4,"*"),$G$2:$G$99) -> 2 | AB4: =SUMIF($A$2:$A$99,CONCATENATE("*",U4,"*"),$H$2:$H$99) -> 0
A5: StxOp1038_Stx1d_4 | F5: 1 | J5: Stx2c | K5: =COUNTIFS(alldata_newdb!Q:Q, CONCATENATE("*",J5,"*"), alldata_newdb!L:L, "Dairy") -> 0 | L5: =COUNTIFS(alldata_newdb!Q:Q, CONCATENATE("*",J5,"*"), alldata_newdb!L:L, "Environment") -> 7 | M5: =COUNTIFS(alldata_newdb!Q:Q, CONCATENATE("*",J5,"*"), alldata_newdb!L:L, "Flour") -> 1 | N5: =COUNTIFS(alldata_newdb!Q:Q, CONCATENATE("*",J5,"*"), alldata_newdb!L:L, "Meat") -> 52 | O5: =COUNTIFS(alldata_newdb!Q:Q, CONCATENATE("*",J5,"*"), alldata_newdb!L:L, "Lamb") -> 0 | P5: =COUNTIFS(alldata_newdb!Q:Q, CONCATENATE("*",J5,"*"), alldata_newdb!L:L, "Nuts/Seeds") -> 3 | Q5: =COUNTIFS(alldata_newdb!Q:Q, CONCATENATE("*",J5,"*"), alldata_newdb!L:L, "Other") -> 4 | R5: =COUNTIFS(alldata_newdb!Q:Q, CONCATENATE("*",J5,"*"), alldata_newdb!L:L, "Vegetable") -> 0 | S5: =SUM(K5:R5) -> 67 | U5: Stx2c | V5: =SUMIF($A$2:$A$99,CONCATENATE("*",U5,"*"),$B$2:$B$99) -> 0 | W5: =SUMIF($A$2:$A$99,CONCATENATE("*",U5,"*"),$C$2:$C$99) -> 7 | X5: =SUMIF($A$2:$A$99,CONCATENATE("*",U5,"*"),$D$2:$D$99) -> 1 | Y5: =SUMIF($A$2:$A$99,CONCATENATE("*",U5,"*"),$E$2:$E$99) -> 52 | Z5: =SUMIF($A$2:$A$99,CONCATENATE("*",U5,"*"),$F$2:$F$99) -> 3 | AA5: =SUMIF($A$2:$A$99,CONCATENATE("*",U5,"*"),$G$2:$G$99) -> 4 | AB5: =SUMIF($A$2:$A$99,CONCATENATE("*",U5,"*"),$H$2:$H$99) -> 0
A6: StxOp1043_Stx2a_1 | E6: 7 | F6: 1 | J6: Stx1c | K6: =COUNTIFS(alldata_newdb!Q:Q, CONCATENATE("*",J6,"*"), alldata_newdb!L:L, "Dairy") -> 0 | L6: =COUNTIFS(alldata_newdb!Q:Q, CONCATENATE("*",J6,"*"), alldata_newdb!L:L, "Environment") -> 0 | M6: =COUNTIFS(alldata_newdb!Q:Q, CONCATENATE("*",J6,"*"), alldata_newdb!L:L, "Flour") -> 1 | N6: =COUNTIFS(alldata_newdb!Q:Q, CONCATENATE("*",J6,"*"), alldata_newdb!L:L, "Meat") -> 52 | O6: =COUNTIFS(alldata_newdb!Q:Q, CONCATENATE("*",J6,"*"), alldata_newdb!L:L, "Lamb") -> 28 | P6: =COUNTIFS(alldata_newdb!Q:Q, CONCATENATE("*",J6,"*"), alldata_newdb!L:L, "Nuts/Seeds") -> 0 | Q6: =COUNTIFS(alldata_newdb!Q:Q, CONCATENATE("*",J6,"*"), alldata_newdb!L:L, "Other") -> 27 | R6: =COUNTIFS(alldata_newdb!Q:Q, CONCATENATE("*",J6,"*"), alldata_newdb!L:L, "Vegetable") -> 0 | S6: =SUM(K6:R6) -> 108 | U6: Stx1c | V6: =SUMIF($A$2:$A$99,CONCATENATE("*",U6,"*"),$B$2:$B$99) -> 0 | W6: =SUMIF($A$2:$A$99,CONCATENATE("*",U6,"*"),$C$2:$C$99) -> 0 | X6: =SUMIF($A$2:$A$99,CONCATENATE("*",U6,"*"),$D$2:$D$99) -> 1 | Y6: =SUMIF($A$2:$A$99,CONCATENATE("*",U6,"*"),$E$2:$E$99) -> 80 | Z6: =SUMIF($A$2:$A$99,CONCATENATE("*",U6,"*"),$F$2:$F$99) -> 0 | AA6: =SUMIF($A$2:$A$99,CONCATENATE("*",U6,"*"),$G$2:$G$99) -> 27 | AB6: =SUMIF($A$2:$A$99,CONCATENATE("*",U6,"*"),$H$2:$H$99) -> 0
A7: StxOp1081_Stx2a_1 | StxOp3_Stx1a_9 | E7: 1 | J7: Stx2b | K7: =COUNTIFS(alldata_newdb!Q:Q, CONCATENATE("*",J7,"*"), alldata_newdb!L:L, "Dairy") -> 0 | L7: =COUNTIFS(alldata_newdb!Q:Q, CONCATENATE("*",J7,"*"), alldata_newdb!L:L, "Environment") -> 0 | M7: =COUNTIFS(alldata_newdb!Q:Q, CONCATENATE("*",J7,"*"), alldata_newdb!L:L, "Flour") -> 0 | N7: =COUNTIFS(alldata_newdb!Q:Q, CONCATENATE("*",J7,"*"), alldata_newdb!L:L, "Meat") -> 63 | O7: =COUNTIFS(alldata_newdb!Q:Q, CONCATENATE("*",J7,"*"), alldata_newdb!L:L, "Lamb") -> 23 | P7: =COUNTIFS(alldata_newdb!Q:Q, CONCATENATE("*",J7,"*"), alldata_newdb!L:L, "Nuts/Seeds") -> 0 | Q7: =COUNTIFS(alldata_newdb!Q:Q, CONCATENATE("*",J7,"*"), alldata_newdb!L:L, "Other") -> 32 | R7: =COUNTIFS(alldata_newdb!Q:Q, CONCATENATE("*",J7,"*"), alldata_newdb!L:L, "Vegetable") -> 0 | S7: =SUM(K7:R7) -> 118 | U7: Stx2b | V7: =SUMIF($A$2:$A$99,CONCATENATE("*",U7,"*"),$B$2:$B$99) -> 0 | W7: =SUMIF($A$2:$A$99,CONCATENATE("*",U7,"*"),$C$2:$C$99) -> 0 | X7: =SUMIF($A$2:$A$99,CONCATENATE("*",U7,"*"),$D$2:$D$99) -> 0 | Y7: =SUMIF($A$2:$A$99,CONCATENATE("*",U7,"*"),$E$2:$E$99) -> 86 | Z7: =SUMIF($A$2:$A$99,CONCATENATE("*",U7,"*"),$F$2:$F$99) -> 0 | AA7: =SUMIF($A$2:$A$99,CONCATENATE("*",U7,"*"),$G$2:$G$99) -> 32 | AB7: =SUMIF($A$2:$A$99,CONCATENATE("*",U7,"*"),$H$2:$H$99) -> 0
A8: StxOp1089_Stx2a_1 | B8: 2 | E8: 34 | F8: 1 | G8: 1 | J8: Stx2k | K8: =COUNTIFS(alldata_newdb!Q:Q, CONCATENATE("*",J8,"*"), alldata_newdb!L:L, "Dairy") -> 0 | L8: =COUNTIFS(alldata_newdb!Q:Q, CONCATENATE("*",J8,"*"), alldata_newdb!L:L, "Environment") -> 0 | M8: =COUNTIFS(alldata_newdb!Q:Q, CONCATENATE("*",J8,"*"), alldata_newdb!L:L, "Flour") -> 0 | N8: =COUNTIFS(alldata_newdb!Q:Q, CONCATENATE("*",J8,"*"), alldata_newdb!L:L, "Meat") -> 1 | O8: =COUNTIFS(alldata_newdb!Q:Q, CONCATENATE("*",J8,"*"), alldata_newdb!L:L, "Lamb") -> 0 | P8: =COUNTIFS(alldata_newdb!Q:Q, CONCATENATE("*",J8,"*"), alldata_newdb!L:L, "Nuts/Seeds") -> 0 | Q8: =COUNTIFS(alldata_newdb!Q:Q, CONCATENATE("*",J8,"*"), alldata_newdb!L:L, "Other") -> 0 | R8: =COUNTIFS(alldata_newdb!Q:Q, CONCATENATE("*",J8,"*"), alldata_newdb!L:L, "Vegetable") -> 0 | S8: =SUM(K8:R8) -> 1 | U8: Stx2k | V8: =SUMIF($A$2:$A$99,CONCATENATE("*",U8,"*"),$B$2:$B$99) -> 0 | W8: =SUMIF($A$2:$A$99,CONCATENATE("*",U8,"*"),$C$2:$C$99) -> 0 | X8: =SUMIF($A$2:$A$99,CONCATENATE("*",U8,"*"),$D$2:$D$99) -> 0 | Y8: =SUMIF($A$2:$A$99,CONCATENATE("*",U8,"*"),$E$2:$E$99) -> 1 | Z8: =SUMIF($A$2:$A$99,CONCATENATE("*",U8,"*"),$F$2:$F$99) -> 0 | AA8: =SUMIF($A$2:$A$99,CONCATENATE("*",U8,"*"),$G$2:$G$99) -> 0 | AB8: =SUMIF($A$2:$A$99,CONCATENATE("*",U8,"*"),$H$2:$H$99) -> 0
A9: StxOp1089_Stx2a_1 | StxOp3_Stx1a_9 | B9: 1 | C9: 2 | E9: 60 | G9: 2 | H9: 1 | J9: Stx2e | K9: =COUNTIFS(alldata_newdb!Q:Q, CONCATENATE("*",J9,"*"), alldata_newdb!L:L, "Dairy") -> 0 | L9: =COUNTIFS(alldata_newdb!Q:Q, CONCATENATE("*",J9,"*"), alldata_newdb!L:L, "Environment") -> 0 | M9: =COUNTIFS(alldata_newdb!Q:Q, CONCATENATE("*",J9,"*"), alldata_newdb!L:L, "Flour") -> 0 | N9: =COUNTIFS(alldata_newdb!Q:Q, CONCATENATE("*",J9,"*"), alldata_newdb!L:L, "Meat") -> 7 | O9: =COUNTIFS(alldata_newdb!Q:Q, CONCATENATE("*",J9,"*"), alldata_newdb!L:L, "Lamb") -> 1 | P9: =COUNTIFS(alldata_newdb!Q:Q, CONCATENATE("*",J9,"*"), alldata_newdb!L:L, "Nuts/Seeds") -> 0 | Q9: =COUNTIFS(alldata_newdb!Q:Q, CONCATENATE("*",J9,"*"), alldata_newdb!L:L, "Other") -> 0 | R9: =COUNTIFS(alldata_newdb!Q:Q, CONCATENATE("*",J9,"*"), alldata_newdb!L:L, "Vegetable") -> 0 | S9: =SUM(K9:R9) -> 8 | U9: Stx2e | V9: =SUMIF($A$2:$A$99,CONCATENATE("*",U9,"*"),$B$2:$B$99) -> 0 | W9: =SUMIF($A$2:$A$99,CONCATENATE("*",U9,"*"),$C$2:$C$99) -> 0 | X9: =SUMIF($A$2:$A$99,CONCATENATE("*",U9,"*"),$D$2:$D$99) -> 0 | Y9: =SUMIF($A$2:$A$99,CONCATENATE("*",U9,"*"),$E$2:$E$99) -> 8 | Z9: =SUMIF($A$2:$A$99,CONCATENATE("*",U9,"*"),$F$2:$F$99) -> 0 | AA9: =SUMIF($A$2:$A$99,CONCATENATE("*",U9,"*"),$G$2:$G$99) -> 0 | AB9: =SUMIF($A$2:$A$99,CONCATENATE("*",U9,"*"),$H$2:$H$99) -> 0
A10: StxOp1096_Stx2a_6 | StxOp16_Stx1a_24 | E10: 1 | J10: Stx2g | K10: =COUNTIFS(alldata_newdb!Q:Q, CONCATENATE("*",J10,"*"), alldata_newdb!L:L, "Dairy") -> 0 | L10: =COUNTIFS(alldata_newdb!Q:Q, CONCATENATE("*",J10,"*"), alldata_newdb!L:L, "Environment") -> 0 | M10: =COUNTIFS(alldata_newdb!Q:Q, CONCATENATE("*",J10,"*"), alldata_newdb!L:L, "Flour") -> 0 | N10: =COUNTIFS(alldata_newdb!Q:Q, CONCATENATE("*",J10,"*"), alldata_newdb!L:L, "Meat") -> 2 | O10: =COUNTIFS(alldata_newdb!Q:Q, CONCATENATE("*",J10,"*"), alldata_newdb!L:L, "Lamb") -> 0 | P10: =COUNTIFS(alldata_newdb!Q:Q, CONCATENATE("*",J10,"*"), alldata_newdb!L:L, "Nuts/Seeds") -> 0 | Q10: =COUNTIFS(alldata_newdb!Q:Q, CONCATENATE("*",J10,"*"), alldata_newdb!L:L, "Other") -> 1 | R10: =COUNTIFS(alldata_newdb!Q:Q, CONCATENATE("*",J10,"*"), alldata_newdb!L:L, "Vegetable") -> 0 | S10: =SUM(K10:R10) -> 3 | U10: Stx2g | V10: =SUMIF($A$2:$A$99,CONCATENATE("*",U10,"*"),$B$2:$B$99) -> 0 | W10: =SUMIF($A$2:$A$99,CONCATENATE("*",U10,"*"),$C$2:$C$99) -> 0 | X10: =SUMIF($A$2:$A$99,CONCATENATE("*",U10,"*"),$D$2:$D$99) -> 0 | Y10: =SUMIF($A$2:$A$99,CONCATENATE("*",U10,"*"),$E$2:$E$99) -> 2 | Z10: =SUMIF($A$2:$A$99,CONCATENATE("*",U10,"*"),$F$2:$F$99) -> 0 | AA10: =SUMIF($A$2:$A$99,CONCATENATE("*",U10,"*"),$G$2:$G$99) -> 1 | AB10: =SUMIF($A$2:$A$99,CONCATENATE("*",U10,"*"),$H$2:$H$99) -> 0
A11: StxOp1157_Stx2a_6 | StxOp4_Stx1a_9 | D11: 1 | E11: 1 | G11: 1 | J11: Stx2i | K11: =COUNTIFS(alldata_newdb!Q:Q, CONCATENATE("*",J11,"*"), alldata_newdb!L:L, "Dairy") -> 0 | L11: =COUNTIFS(alldata_newdb!Q:Q, CONCATENATE("*",J11,"*"), alldata_newdb!L:L, "Environment") -> 0 | M11: =COUNTIFS(alldata_newdb!Q:Q, CONCATENATE("*",J11,"*"), alldata_newdb!L:L, "Flour") -> 0 | N11: =COUNTIFS(alldata_newdb!Q:Q, CONCATENATE("*",J11,"*"), alldata_newdb!L:L, "Meat") -> 0 | O11: =COUNTIFS(alldata_newdb!Q:Q, CONCATENATE("*",J11,"*"), alldata_newdb!L:L, "Lamb") -> 12 | P11: =COUNTIFS(alldata_newdb!Q:Q, CONCATENATE("*",J11,"*"), alldata_newdb!L:L, "Nuts/Seeds") -> 0 | Q11: =COUNTIFS(alldata_newdb!Q:Q, CONCATENATE("*",J11,"*"), alldata_newdb!L:L, "Other") -> 4 | R11: =COUNTIFS(alldata_newdb!Q:Q, CONCATENATE("*",J11,"*"), alldata_newdb!L:L, "Vegetable") -> 0 | S11: =SUM(K11:R11) -> 16 | U11: Stx2i | V11: =SUMIF($A$2:$A$99,CONCATENATE("*",U11,"*"),$B$2:$B$99) -> 0 | W11: =SUMIF($A$2:$A$99,CONCATENATE("*",U11,"*"),$C$2:$C$99) -> 0 | X11: =SUMIF($A$2:$A$99,CONCATENATE("*",U11,"*"),$D$2:$D$99) -> 0 | Y11: =SUMIF($A$2:$A$99,CONCATENATE("*",U11,"*"),$E$2:$E$99) -> 12 | Z11: =SUMIF($A$2:$A$99,CONCATENATE("*",U11,"*"),$F$2:$F$99) -> 0 | AA11: =SUMIF($A$2:$A$99,CONCATENATE("*",U11,"*"),$G$2:$G$99) -> 4 | AB11: =SUMIF($A$2:$A$99,CONCATENATE("*",U11,"*"),$H$2:$H$99) -> 0
A12: StxOp1168_Stx2a_16 | StxOp1645_Stx1a_9 | E12: 1 | G12: 1 | J12: Stx1d | K12: =COUNTIFS(alldata_newdb!Q:Q, CONCATENATE("*",J12,"*"), alldata_newdb!L:L, "Dairy") -> 0 | L12: =COUNTIFS(alldata_newdb!Q:Q, CONCATENATE("*",J12,"*"), alldata_newdb!L:L, "Environment") -> 0 | M12: =COUNTIFS(alldata_newdb!Q:Q, CONCATENATE("*",J12,"*"), alldata_newdb!L:L, "Flour") -> 0 | N12: =COUNTIFS(alldata_newdb!Q:Q, CONCATENATE("*",J12,"*"), alldata_newdb!L:L, "Meat") -> 0 | O12: =COUNTIFS(alldata_newdb!Q:Q, CONCATENATE("*",J12,"*"), alldata_newdb!L:L, "Lamb") -> 0 | P12: =COUNTIFS(alldata_newdb!Q:Q, CONCATENATE("*",J12,"*"), alldata_newdb!L:L, "Nuts/Seeds") -> 1 | Q12: =COUNTIFS(alldata_newdb!Q:Q, CONCATENATE("*",J12,"*"), alldata_newdb!L:L, "Other") -> 0 | R12: =COUNTIFS(alldata_newdb!Q:Q, CONCATENATE("*",J12,"*"), alldata_newdb!L:L, "Vegetable") -> 0 | S12: =SUM(K12:R12) -> 1 | U12: Stx1d | V12: =SUMIF($A$2:$A$99,CONCATENATE("*",U12,"*"),$B$2:$B$99) -> 0 | W12: =SUMIF($A$2:$A$99,CONCATENATE("*",U12,"*"),$C$2:$C$99) -> 0 | X12: =SUMIF($A$2:$A$99,CONCATENATE("*",U12,"*"),$D$2:$D$99) -> 0 | Y12: =SUMIF($A$2:$A$99,CONCATENATE("*",U12,"*"),$E$2:$E$99) -> 0 | Z12: =SUMIF($A$2:$A$99,CONCATENATE("*",U12,"*"),$F$2:$F$99) -> 1 | AA12: =SUMIF($A$2:$A$99,CONCATENATE("*",U12,"*"),$G$2:$G$99) -> 0 | AB12: =SUMIF($A$2:$A$99,CONCATENATE("*",U12,"*"),$H$2:$H$99) -> 0
A13: StxOp1168_Stx2a_16 | StxOp966_Stx1a_18 | F13: 3
A14: StxOp1173_Stx2a_16 | E14: 2
A15: StxOp1173_Stx2a_16 | StxOp1348_Stx2b_110 | StxOp400_Stx1c_22 | E15: 1
A16: StxOp1173_Stx2a_16 | StxOp969_Stx1a_19 | E16: 1 | J16: countifs (to count number of rows | K16: Dairy | L16: Environment | M16: Flour | N16: Meat | O16: Lamb | P16: Nuts/Seeds | Q16: Other | R16: Vegetable | S16: TOTAL | U16: Protein Allele | V16: Dairy | W16: Environment | X16: Flour | Y16: Meat | Z16: Nuts/Seeds | AA16: Other | AB16: Vegetable
A17: StxOp1250_Stx2a_127 | StxOp4_Stx1a_9 | E17: 2 | J17: Stx1a | K17: 8 | L17: 3 | M17: 5 | N17: 195 | O17: 8 | P17: 4 | Q17: 20 | R17: 2 | S17: 245 | U17: Stx1a | V17: 8 | W17: 3 | X17: 5 | Y17: 203 | Z17: 4 | AA17: 20 | AB17: 2
A18: StxOp1287_Stx2a_183 | E18: 1 | J18: Stx2a | K18: 10 | L18: 2 | M18: 23 | N18: 175 | O18: 0 | P18: 14 | Q18: 10 | R18: 4 | S18: 238 | U18: Stx2a | V18: 10 | W18: 2 | X18: 23 | Y18: 175 | Z18: 14 | AA18: 10 | AB18: 4
A19: StxOp1329_Stx2b_101 | StxOp13_Stx1a_19 | E19: 2 | J19: Stx2d | K19: 3 | L19: 0 | M19: 0 | N19: 15 | O19: 0 | P19: 0 | Q19: 2 | R19: 0 | S19: 20 | U19: Stx2d | V19: 3 | W19: 0 | X19: 0 | Y19: 15 | Z19: 0 | AA19: 2 | AB19: 0
A20: StxOp1336_Stx2b_109 | StxOp13_Stx1a_19 | E20: 1 | G20: 1 | J20: Stx2c | K20: 0 | L20: 7 | M20: 1 | N20: 52 | O20: 0 | P20: 3 | Q20: 4 | R20: 0 | S20: 67 | U20: Stx2c | V20: 0 | W20: 7 | X20: 1 | Y20: 52 | Z20: 3 | AA20: 4 | AB20: 0
A21: StxOp1336_Stx2b_109 | StxOp399_Stx1c_12 | E21: 2 | G21: 1 | J21: Stx1c | K21: 0 | L21: 0 | M21: 1 | N21: 52 | O21: 28 | P21: 0 | Q21: 27 | R21: 0 | S21: 108 | U21: Stx1c | V21: 0 | W21: 0 | X21: 1 | Y21: 80 | Z21: 0 | AA21: 27 | AB21: 0
A22: StxOp1339_Stx2b_109 | E22: 1 | G22: 1 | J22: Stx2b | K22: 0 | L22: 0 | M22: 0 | N22: 63 | O22: 23 | P22: 0 | Q22: 32 | R22: 0 | S22: 118 | U22: Stx2b | V22: 0 | W22: 0 | X22: 0 | Y22: 86 | Z22: 0 | AA22: 32 | AB22: 0
A23: StxOp1339_Stx2b_109 | StxOp1037_Stx1c_26 | E23: 3 | G23: 1 | J23: Stx2k | K23: 0 | L23: 0 | M23: 0 | N23: 1 | O23: 0 | P23: 0 | Q23: 0 | R23: 0 | S23: 1 | U23: Stx2k | V23: 0 | W23: 0 | X23: 0 | Y23: 1 | Z23: 0 | AA23: 0 | AB23: 0
A24: StxOp1339_Stx2b_109 | StxOp399_Stx1c_12 | E24: 1 | J24: Stx2e | K24: 0 | L24: 0 | M24: 0 | N24: 7 | O24: 1 | P24: 0 | Q24: 0 | R24: 0 | S24: 8 | U24: Stx2e | V24: 0 | W24: 0 | X24: 0 | Y24: 8 | Z24: 0 | AA24: 0 | AB24: 0
A25: StxOp1339_Stx2b_109 | StxOp401_Stx1c_23 | E25: 1 | J25: Stx2g | K25: 0 | L25: 0 | M25: 0 | N25: 2 | O25: 0 | P25: 0 | Q25: 1 | R25: 0 | S25: 3 | U25: Stx2g | V25: 0 | W25: 0 | X25: 0 | Y25: 2 | Z25: 0 | AA25: 1 | AB25: 0
A26: StxOp1339_Stx2b_109 | StxOp4754_Stx1c_708 | E26: 4 | G26: 2 | J26: Stx2i | K26: 0 | L26: 0 | M26: 0 | N26: 0 | O26: 12 | P26: 0 | Q26: 4 | R26: 0 | S26: 16 | U26: Stx2i | V26: 0 | W26: 0 | X26: 0 | Y26: 12 | Z26: 0 | AA26: 4 | AB26: 0
A27: StxOp1344_Stx2b_109 | E27: 1 | G27: 1 | J27: Stx1d | K27: 0 | L27: 0 | M27: 0 | N27: 0 | O27: 0 | P27: 1 | Q27: 0 | R27: 0 | S27: 1 | U27: Stx1d | V27: 0 | W27: 0 | X27: 0 | Y27: 0 | Z27: 1 | AA27: 0 | AB27: 0
A28: StxOp1346_Stx2b_110 | StxOp13_Stx1a_19 | E28: 1
A29: StxOp1346_Stx2b_110 | StxOp399_Stx1c_12 | E29: 1 | J29: NO O157
A30: StxOp1348_Stx2b_110 | StxOp1037_Stx1c_26 | E30: 2 | J30: countifs (to count number of rows | K30: Dairy | L30: Environment | M30: Flour | N30: Meat | O30: Lamb | P30: Nuts/Seeds | Q30: Other | R30: Vegetable | S30: TOTAL
A31: StxOp1348_Stx2b_110 | StxOp13_Stx1a_19 | E31: 1 | J31: Stx1a | K31: =COUNTIFS(alldata_newdb!M:M, "<>O157:H7", alldata_newdb!Q:Q, CONCATENATE("*",J31,"*"), alldata_newdb!L:L, "Dairy") -> 0 | L31: =COUNTIFS(alldata_newdb!M:M, "<>O157:H7",alldata_newdb!Q:Q, CONCATENATE("*",J31,"*"), alldata_newdb!L:L, "Environment") -> 0 | M31: =COUNTIFS(alldata_newdb!M:M, "<>O157:H7",alldata_newdb!Q:Q, CONCATENATE("*",J31,"*"), alldata_newdb!L:L, "Flour") -> 5 | N31: =COUNTIFS(alldata_newdb!M:M, "<>O157:H7",alldata_newdb!Q:Q, CONCATENATE("*",J31,"*"), alldata_newdb!L:L, "Meat") -> 61 | O31: =COUNTIFS(alldata_newdb!M:M, "<>O157:H7",alldata_newdb!Q:Q, CONCATENATE("*",J31,"*"), alldata_newdb!L:L, "Lamb") -> 8 | P31: =COUNTIFS(alldata_newdb!M:M, "<>O157:H7",alldata_newdb!Q:Q, CONCATENATE("*",J31,"*"), alldata_newdb!L:L, "Nuts/Seeds") -> 4 | Q31: =COUNTIFS(alldata_newdb!M:M, "<>O157:H7",alldata_newdb!Q:Q, CONCATENATE("*",J31,"*"), alldata_newdb!L:L, "Other") -> 15 | R31: =COUNTIFS(alldata_newdb!M:M, "<>O157:H7",alldata_newdb!Q:Q, CONCATENATE("*",J31,"*"), alldata_newdb!L:L, "Vegetable") -> 0 | S31: =SUM(K31:R31) -> 93
A32: StxOp1348_Stx2b_110 | StxOp2167_Stx1c_500 | E32: 1 | J32: Stx2a | K32: =COUNTIFS(alldata_newdb!M:M, "<>O157:H7", alldata_newdb!Q:Q, CONCATENATE("*",J32,"*"), alldata_newdb!L:L, "Dairy") -> 0 | L32: =COUNTIFS(alldata_newdb!M:M, "<>O157:H7",alldata_newdb!Q:Q, CONCATENATE("*",J32,"*"), alldata_newdb!L:L, "Environment") -> 0 | M32: =COUNTIFS(alldata_newdb!M:M, "<>O157:H7",alldata_newdb!Q:Q, CONCATENATE("*",J32,"*"), alldata_newdb!L:L, "Flour") -> 23 | N32: =COUNTIFS(alldata_newdb!M:M, "<>O157:H7",alldata_newdb!Q:Q, CONCATENATE("*",J32,"*"), alldata_newdb!L:L, "Meat") -> 18 | O32: =COUNTIFS(alldata_newdb!M:M, "<>O157:H7",alldata_newdb!Q:Q, CONCATENATE("*",J32,"*"), alldata_newdb!L:L, "Lamb") -> 0 | P32: =COUNTIFS(alldata_newdb!M:M, "<>O157:H7",alldata_newdb!Q:Q, CONCATENATE("*",J32,"*"), alldata_newdb!L:L, "Nuts/Seeds") -> 13 | Q32: =COUNTIFS(alldata_newdb!M:M, "<>O157:H7",alldata_newdb!Q:Q, CONCATENATE("*",J32,"*"), alldata_newdb!L:L, "Other") -> 8 | R32: =COUNTIFS(alldata_newdb!M:M, "<>O157:H7",alldata_newdb!Q:Q, CONCATENATE("*",J32,"*"), alldata_newdb!L:L, "Vegetable") -> 2 | S32: =SUM(K32:R32) -> 64
A33: StxOp1348_Stx2b_110 | StxOp399_Stx1c_12 | E33: 7 | G33: 2 | J33: Stx2d | K33: =COUNTIFS(alldata_newdb!M:M, "<>O157:H7", alldata_newdb!Q:Q, CONCATENATE("*",J33,"*"), alldata_newdb!L:L, "Dairy") -> 3 | L33: =COUNTIFS(alldata_newdb!M:M, "<>O157:H7",alldata_newdb!Q:Q, CONCATENATE("*",J33,"*"), alldata_newdb!L:L, "Environment") -> 0 | M33: =COUNTIFS(alldata_newdb!M:M, "<>O157:H7",alldata_newdb!Q:Q, CONCATENATE("*",J33,"*"), alldata_newdb!L:L, "Flour") -> 0 | N33: =COUNTIFS(alldata_newdb!M:M, "<>O157:H7",alldata_newdb!Q:Q, CONCATENATE("*",J33,"*"), alldata_newdb!L:L, "Meat") -> 15 | O33: =COUNTIFS(alldata_newdb!M:M, "<>O157:H7",alldata_newdb!Q:Q, CONCATENATE("*",J33,"*"), alldata_newdb!L:L, "Lamb") -> 0 | P33: =COUNTIFS(alldata_newdb!M:M, "<>O157:H7",alldata_newdb!Q:Q, CONCATENATE("*",J33,"*"), alldata_newdb!L:L, "Nuts/Seeds") -> 0 | Q33: =COUNTIFS(alldata_newdb!M:M, "<>O157:H7",alldata_newdb!Q:Q, CONCATENATE("*",J33,"*"), alldata_newdb!L:L, "Other") -> 2 | R33: =COUNTIFS(alldata_newdb!M:M, "<>O157:H7",alldata_newdb!Q:Q, CONCATENATE("*",J33,"*"), alldata_newdb!L:L, "Vegetable") -> 0 | S33: =SUM(K33:R33) -> 20
A34: StxOp1348_Stx2b_110 | StxOp400_Stx1c_22 | E34: 2 | J34: Stx2c | K34: =COUNTIFS(alldata_newdb!M:M, "<>O157:H7", alldata_newdb!Q:Q, CONCATENATE("*",J34,"*"), alldata_newdb!L:L, "Dairy") -> 0 | L34: =COUNTIFS(alldata_newdb!M:M, "<>O157:H7",alldata_newdb!Q:Q, CONCATENATE("*",J34,"*"), alldata_newdb!L:L, "Environment") -> 0 | M34: =COUNTIFS(alldata_newdb!M:M, "<>O157:H7",alldata_newdb!Q:Q, CONCATENATE("*",J34,"*"), alldata_newdb!L:L, "Flour") -> 1 | N34: =COUNTIFS(alldata_newdb!M:M, "<>O157:H7",alldata_newdb!Q:Q, CONCATENATE("*",J34,"*"), alldata_newdb!L:L, "Meat") -> 15 | O34: =COUNTIFS(alldata_newdb!M:M, "<>O157:H7",alldata_newdb!Q:Q, CONCATENATE("*",J34,"*"), alldata_newdb!L:L, "Lamb") -> 0 | P34: =COUNTIFS(alldata_newdb!M:M, "<>O157:H7",alldata_newdb!Q:Q, CONCATENATE("*",J34,"*"), alldata_newdb!L:L, "Nuts/Seeds") -> 3 | Q34: =COUNTIFS(alldata_newdb!M:M, "<>O157:H7",alldata_newdb!Q:Q, CONCATENATE("*",J34,"*"), alldata_newdb!L:L, "Other") -> 4 | R34: =COUNTIFS(alldata_newdb!M:M, "<>O157:H7",alldata_newdb!Q:Q, CONCATENATE("*",J34,"*"), alldata_newdb!L:L, "Vegetable") -> 0 | S34: =SUM(K34:R34) -> 23
A35: StxOp1348_Stx2b_110 | StxOp402_Stx1c_25 | E35: 1 | G35: 1 | J35: Stx1c | K35: =COUNTIFS(alldata_newdb!M:M, "<>O157:H7", alldata_newdb!Q:Q, CONCATENATE("*",J35,"*"), alldata_newdb!L:L, "Dairy") -> 0 | L35: =COUNTIFS(alldata_newdb!M:M, "<>O157:H7",alldata_newdb!Q:Q, CONCATENATE("*",J35,"*"), alldata_newdb!L:L, "Environment") -> 0 | M35: =COUNTIFS(alldata_newdb!M:M, "<>O157:H7",alldata_newdb!Q:Q, CONCATENATE("*",J35,"*"), alldata_newdb!L:L, "Flour") -> 1 | N35: =COUNTIFS(alldata_newdb!M:M, "<>O157:H7",alldata_newdb!Q:Q, CONCATENATE("*",J35,"*"), alldata_newdb!L:L, "Meat") -> 52 | O35: =COUNTIFS(alldata_newdb!M:M, "<>O157:H7",alldata_newdb!Q:Q, CONCATENATE("*",J35,"*"), alldata_newdb!L:L, "Lamb") -> 28 | P35: =COUNTIFS(alldata_newdb!M:M, "<>O157:H7",alldata_newdb!Q:Q, CONCATENATE("*",J35,"*"), alldata_newdb!L:L, "Nuts/Seeds") -> 0 | Q35: =COUNTIFS(alldata_newdb!M:M, "<>O157:H7",alldata_newdb!Q:Q, CONCATENATE("*",J35,"*"), alldata_newdb!L:L, "Other") -> 24 | R35: =COUNTIFS(alldata_newdb!M:M, "<>O157:H7",alldata_newdb!Q:Q, CONCATENATE("*",J35,"*"), alldata_newdb!L:L, "Vegetable") -> 0 | S35: =SUM(K35:R35) -> 105
A36: StxOp1348_Stx2b_110 | StxOp4754_Stx1c_708 | E36: 11 | G36: 8 | J36: Stx2b | K36: =COUNTIFS(alldata_newdb!M:M, "<>O157:H7", alldata_newdb!Q:Q, CONCATENATE("*",J36,"*"), alldata_newdb!L:L, "Dairy") -> 0 | L36: =COUNTIFS(alldata_newdb!M:M, "<>O157:H7",alldata_newdb!Q:Q, CONCATENATE("*",J36,"*"), alldata_newdb!L:L, "Environment") -> 0 | M36: =COUNTIFS(alldata_newdb!M:M, "<>O157:H7",alldata_newdb!Q:Q, CONCATENATE("*",J36,"*"), alldata_newdb!L:L, "Flour") -> 0 | N36: =COUNTIFS(alldata_newdb!M:M, "<>O157:H7",alldata_newdb!Q:Q, CONCATENATE("*",J36,"*"), alldata_newdb!L:L, "Meat") -> 63 | O36: =COUNTIFS(alldata_newdb!M:M, "<>O157:H7",alldata_newdb!Q:Q, CONCATENATE("*",J36,"*"), alldata_newdb!L:L, "Lamb") -> 23 | P36: =COUNTIFS(alldata_newdb!M:M, "<>O157:H7",alldata_newdb!Q:Q, CONCATENATE("*",J36,"*"), alldata_newdb!L:L, "Nuts/Seeds") -> 0 | Q36: =COUNTIFS(alldata_newdb!M:M, "<>O157:H7",alldata_newdb!Q:Q, CONCATENATE("*",J36,"*"), alldata_newdb!L:L, "Other") -> 27 | R36: =COUNTIFS(alldata_newdb!M:M, "<>O157:H7",alldata_newdb!Q:Q, CONCATENATE("*",J36,"*"), alldata_newdb!L:L, "Vegetable") -> 0 | S36: =SUM(K36:R36) -> 113
A37: StxOp1352_Stx2b_116 | StxOp13_Stx1a_19 | E37: 1 | J37: Stx2k | K37: =COUNTIFS(alldata_newdb!M:M, "<>O157:H7", alldata_newdb!Q:Q, CONCATENATE("*",J37,"*"), alldata_newdb!L:L, "Dairy") -> 0 | L37: =COUNTIFS(alldata_newdb!M:M, "<>O157:H7",alldata_newdb!Q:Q, CONCATENATE("*",J37,"*"), alldata_newdb!L:L, "Environment") -> 0 | M37: =COUNTIFS(alldata_newdb!M:M, "<>O157:H7",alldata_newdb!Q:Q, CONCATENATE("*",J37,"*"), alldata_newdb!L:L, "Flour") -> 0 | N37: =COUNTIFS(alldata_newdb!M:M, "<>O157:H7",alldata_newdb!Q:Q, CONCATENATE("*",J37,"*"), alldata_newdb!L:L, "Meat") -> 1 | O37: =COUNTIFS(alldata_newdb!M:M, "<>O157:H7",alldata_newdb!Q:Q, CONCATENATE("*",J37,"*"), alldata_newdb!L:L, "Lamb") -> 0 | P37: =COUNTIFS(alldata_newdb!M:M, "<>O157:H7",alldata_newdb!Q:Q, CONCATENATE("*",J37,"*"), alldata_newdb!L:L, "Nuts/Seeds") -> 0 | Q37: =COUNTIFS(alldata_newdb!M:M, "<>O157:H7",alldata_newdb!Q:Q, CONCATENATE("*",J37,"*"), alldata_newdb!L:L, "Other") -> 0 | R37: =COUNTIFS(alldata_newdb!M:M, "<>O157:H7",alldata_newdb!Q:Q, CONCATENATE("*",J37,"*"), alldata_newdb!L:L, "Vegetable") -> 0 | S37: =SUM(K37:R37) -> 1
A38: StxOp1364_Stx2c_7 | E38: 1 | F38: 1 | G38: 1 | J38: Stx2e | K38: =COUNTIFS(alldata_newdb!M:M, "<>O157:H7", alldata_newdb!Q:Q, CONCATENATE("*",J38,"*"), alldata_newdb!L:L, "Dairy") -> 0 | L38: =COUNTIFS(alldata_newdb!M:M, "<>O157:H7",alldata_newdb!Q:Q, CONCATENATE("*",J38,"*"), alldata_newdb!L:L, "Environment") -> 0 | M38: =COUNTIFS(alldata_newdb!M:M, "<>O157:H7",alldata_newdb!Q:Q, CONCATENATE("*",J38,"*"), alldata_newdb!L:L, "Flour") -> 0 | N38: =COUNTIFS(alldata_newdb!M:M, "<>O157:H7",alldata_newdb!Q:Q, CONCATENATE("*",J38,"*"), alldata_newdb!L:L, "Meat") -> 7 | O38: =COUNTIFS(alldata_newdb!M:M, "<>O157:H7",alldata_newdb!Q:Q, CONCATENATE("*",J38,"*"), alldata_newdb!L:L, "Lamb") -> 1 | P38: =COUNTIFS(alldata_newdb!M:M, "<>O157:H7",alldata_newdb!Q:Q, CONCATENATE("*",J38,"*"), alldata_newdb!L:L, "Nuts/Seeds") -> 0 | Q38: =COUNTIFS(alldata_newdb!M:M, "<>O157:H7",alldata_newdb!Q:Q, CONCATENATE("*",J38,"*"), alldata_newdb!L:L, "Other") -> 0 | R38: =COUNTIFS(alldata_newdb!M:M, "<>O157:H7",alldata_newdb!Q:Q, CONCATENATE("*",J38,"*"), alldata_newdb!L:L, "Vegetable") -> 0 | S38: =SUM(K38:R38) -> 8
A39: StxOp1365_Stx2c_7 | E39: 9 | G39: 2 | J39: Stx2g | K39: =COUNTIFS(alldata_newdb!M:M, "<>O157:H7", alldata_newdb!Q:Q, CONCATENATE("*",J39,"*"), alldata_newdb!L:L, "Dairy") -> 0 | L39: =COUNTIFS(alldata_newdb!M:M, "<>O157:H7",alldata_newdb!Q:Q, CONCATENATE("*",J39,"*"), alldata_newdb!L:L, "Environment") -> 0 | M39: =COUNTIFS(alldata_newdb!M:M, "<>O157:H7",alldata_newdb!Q:Q, CONCATENATE("*",J39,"*"), alldata_newdb!L:L, "Flour") -> 0 | N39: =COUNTIFS(alldata_newdb!M:M, "<>O157:H7",alldata_newdb!Q:Q, CONCATENATE("*",J39,"*"), alldata_newdb!L:L, "Meat") -> 2 | O39: =COUNTIFS(alldata_newdb!M:M, "<>O157:H7",alldata_newdb!Q:Q, CONCATENATE("*",J39,"*"), alldata_newdb!L:L, "Lamb") -> 0 | P39: =COUNTIFS(alldata_newdb!M:M, "<>O157:H7",alldata_newdb!Q:Q, CONCATENATE("*",J39,"*"), alldata_newdb!L:L, "Nuts/Seeds") -> 0 | Q39: =COUNTIFS(alldata_newdb!M:M, "<>O157:H7",alldata_newdb!Q:Q, CONCATENATE("*",J39,"*"), alldata_newdb!L:L, "Other") -> 1 | R39: =COUNTIFS(alldata_newdb!M:M, "<>O157:H7",alldata_newdb!Q:Q, CONCATENATE("*",J39,"*"), alldata_newdb!L:L, "Vegetable") -> 0 | S39: =SUM(K39:R39) -> 3
A40: StxOp1448_Stx2c_152 | E40: 1 | J40: Stx2i | K40: =COUNTIFS(alldata_newdb!M:M, "<>O157:H7", alldata_newdb!Q:Q, CONCATENATE("*",J40,"*"), alldata_newdb!L:L, "Dairy") -> 0 | L40: =COUNTIFS(alldata_newdb!M:M, "<>O157:H7",alldata_newdb!Q:Q, CONCATENATE("*",J40,"*"), alldata_newdb!L:L, "Environment") -> 0 | M40: =COUNTIFS(alldata_newdb!M:M, "<>O157:H7",alldata_newdb!Q:Q, CONCATENATE("*",J40,"*"), alldata_newdb!L:L, "Flour") -> 0 | N40: =COUNTIFS(alldata_newdb!M:M, "<>O157:H7",alldata_newdb!Q:Q, CONCATENATE("*",J40,"*"), alldata_newdb!L:L, "Meat") -> 0 | O40: =COUNTIFS(alldata_newdb!M:M, "<>O157:H7",alldata_newdb!Q:Q, CONCATENATE("*",J40,"*"), alldata_newdb!L:L, "Lamb") -> 12 | P40: =COUNTIFS(alldata_newdb!M:M, "<>O157:H7",alldata_newdb!Q:Q, CONCATENATE("*",J40,"*"), alldata_newdb!L:L, "Nuts/Seeds") -> 0 | Q40: =COUNTIFS(alldata_newdb!M:M, "<>O157:H7",alldata_newdb!Q:Q, CONCATENATE("*",J40,"*"), alldata_newdb!L:L, "Other") -> 2 | R40: =COUNTIFS(alldata_newdb!M:M, "<>O157:H7",alldata_newdb!Q:Q, CONCATENATE("*",J40,"*"), alldata_newdb!L:L, "Vegetable") -> 0 | S40: =SUM(K40:R40) -> 14
...

Sheet new_stx_by_source
A1: Count of Source1 | B1: Column Labels | N1: countifs (to count number of rows | O1: Dairy | P1: Environment | Q1: Flour | R1: Meat | S1: Lamb | T1: Nuts/Seeds | U1: Other | V1: Vegetable | W1: TOTAL
A2: Row Labels | B2: Dairy | C2: Environment | D2: Flour | E2: Meat | F2: Nuts/Seeds | G2: Other | H2: Vegetable | I2: (blank) | J2: Grand Total | N2: Stx1a | O2: =SUMIF($A$3:$A$27,CONCATENATE("*",N2,"*"),$B$3:$B$27) -> 8 | P2: =SUMIF($A$3:$A$27,CONCATENATE("*",N2,"*"),$C$3:$C$27) -> 3 | Q2: =SUMIF($A$3:$A$27,CONCATENATE("*",N2,"*"),$D$3:$D$27) -> 5 | R2: =SUMIF($A$3:$A$27,CONCATENATE("*",N2,"*"),$E$3:$E$27) -> 204 | T2: =SUMIF($A$3:$A$27,CONCATENATE("*",N2,"*"),$F$3:$F$27) -> 4 | U2: =SUMIF($A$3:$A$27,CONCATENATE("*",N2,"*"),$G$3:$G$27) -> 1 | V2: =SUMIF($A$3:$A$27,CONCATENATE("*",N2,"*"),$H$3:$H$27) -> 2 | W2: =SUMIF($A$3:$A$27,CONCATENATE("*",N2,"*"),$J$3:$J$27) -> 227 | Y2: 227
A3: ND | E3: 4 | J3: 4 | N3: Stx2a | O3: =SUMIF($A$3:$A$27,CONCATENATE("*",N3,"*"),$B$3:$B$27) -> 10 | P3: =SUMIF($A$3:$A$27,CONCATENATE("*",N3,"*"),$C$3:$C$27) -> 2 | Q3: =SUMIF($A$3:$A$27,CONCATENATE("*",N3,"*"),$D$3:$D$27) -> 23 | R3: =SUMIF($A$3:$A$27,CONCATENATE("*",N3,"*"),$E$3:$E$27) -> 176 | T3: =SUMIF($A$3:$A$27,CONCATENATE("*",N3,"*"),$F$3:$F$27) -> 14 | U3: =SUMIF($A$3:$A$27,CONCATENATE("*",N3,"*"),$G$3:$G$27) -> 1 | V3: =SUMIF($A$3:$A$27,CONCATENATE("*",N3,"*"),$H$3:$H$27) -> 4 | W3: =SUMIF($A$3:$A$27,CONCATENATE("*",N3,"*"),$J$3:$J$27) -> 230 | Y3: 230
A4: Stx1a | D4: 4 | E4: 33 | J4: 37 | N4: Stx2d | O4: =SUMIF($A$3:$A$27,CONCATENATE("*",N4,"*"),$B$3:$B$27) -> 3 | P4: =SUMIF($A$3:$A$27,CONCATENATE("*",N4,"*"),$C$3:$C$27) -> 0 | Q4: =SUMIF($A$3:$A$27,CONCATENATE("*",N4,"*"),$D$3:$D$27) -> 0 | R4: =SUMIF($A$3:$A$27,CONCATENATE("*",N4,"*"),$E$3:$E$27) -> 15 | T4: =SUMIF($A$3:$A$27,CONCATENATE("*",N4,"*"),$F$3:$F$27) -> 0 | U4: =SUMIF($A$3:$A$27,CONCATENATE("*",N4,"*"),$G$3:$G$27) -> 0 | V4: =SUMIF($A$3:$A$27,CONCATENATE("*",N4,"*"),$H$3:$H$27) -> 0 | W4: =SUMIF($A$3:$A$27,CONCATENATE("*",N4,"*"),$J$3:$J$27) -> 18 | Y4: 18
A5: Stx1a,Stx2a | B5: 7 | E5: 60 | F5: 1 | H5: 1 | J5: 69 | N5: Stx2c | O5: =SUMIF($A$3:$A$27,CONCATENATE("*",N5,"*"),$B$3:$B$27) -> 0 | P5: =SUMIF($A$3:$A$27,CONCATENATE("*",N5,"*"),$C$3:$C$27) -> 7 | Q5: =SUMIF($A$3:$A$27,CONCATENATE("*",N5,"*"),$D$3:$D$27) -> 1 | R5: =SUMIF($A$3:$A$27,CONCATENATE("*",N5,"*"),$E$3:$E$27) -> 52 | T5: =SUMIF($A$3:$A$27,CONCATENATE("*",N5,"*"),$F$3:$F$27) -> 3 | U5: =SUMIF($A$3:$A$27,CONCATENATE("*",N5,"*"),$G$3:$G$27) -> 0 | V5: =SUMIF($A$3:$A$27,CONCATENATE("*",N5,"*"),$H$3:$H$27) -> 0 | W5: =SUMIF($A$3:$A$27,CONCATENATE("*",N5,"*"),$J$3:$J$27) -> 63 | Y5: 63
A6: Stx1a,Stx2c | E6: 7 | J6: 7 | N6: Stx1c | O6: =SUMIF($A$3:$A$27,CONCATENATE("*",N6,"*"),$B$3:$B$27) -> 0 | P6: =SUMIF($A$3:$A$27,CONCATENATE("*",N6,"*"),$C$3:$C$27) -> 0 | Q6: =SUMIF($A$3:$A$27,CONCATENATE("*",N6,"*"),$D$3:$D$27) -> 1 | R6: =SUMIF($A$3:$A$27,CONCATENATE("*",N6,"*"),$E$3:$E$27) -> 80 | T6: =SUMIF($A$3:$A$27,CONCATENATE("*",N6,"*"),$F$3:$F$27) -> 0 | U6: =SUMIF($A$3:$A$27,CONCATENATE("*",N6,"*"),$G$3:$G$27) -> 0 | V6: =SUMIF($A$3:$A$27,CONCATENATE("*",N6,"*"),$H$3:$H$27) -> 0 | W6: =SUMIF($A$3:$A$27,CONCATENATE("*",N6,"*"),$J$3:$J$27) -> 81 | Y6: 81
A7: Stx1c | D7: 1 | E7: 35 | J7: 36 | N7: Stx2b | O7: =SUMIF($A$3:$A$27,CONCATENATE("*",N7,"*"),$B$3:$B$27) -> 0 | P7: =SUMIF($A$3:$A$27,CONCATENATE("*",N7,"*"),$C$3:$C$27) -> 0 | Q7: =SUMIF($A$3:$A$27,CONCATENATE("*",N7,"*"),$D$3:$D$27) -> 0 | R7: =SUMIF($A$3:$A$27,CONCATENATE("*",N7,"*"),$E$3:$E$27) -> 86 | T7: =SUMIF($A$3:$A$27,CONCATENATE("*",N7,"*"),$F$3:$F$27) -> 0 | U7: =SUMIF($A$3:$A$27,CONCATENATE("*",N7,"*"),$G$3:$G$27) -> 0 | V7: =SUMIF($A$3:$A$27,CONCATENATE("*",N7,"*"),$H$3:$H$27) -> 0 | W7: =SUMIF($A$3:$A$27,CONCATENATE("*",N7,"*"),$J$3:$J$27) -> 86 | Y7: 86
A8: Stx1c,Stx2b | E8: 1 | J8: 1 | N8: Stx2k | O8: =SUMIF($A$3:$A$27,CONCATENATE("*",N8,"*"),$B$3:$B$27) -> 0 | P8: =SUMIF($A$3:$A$27,CONCATENATE("*",N8,"*"),$C$3:$C$27) -> 0 | Q8: =SUMIF($A$3:$A$27,CONCATENATE("*",N8,"*"),$D$3:$D$27) -> 0 | R8: =SUMIF($A$3:$A$27,CONCATENATE("*",N8,"*"),$E$3:$E$27) -> 1 | T8: =SUMIF($A$3:$A$27,CONCATENATE("*",N8,"*"),$F$3:$F$27) -> 0 | U8: =SUMIF($A$3:$A$27,CONCATENATE("*",N8,"*"),$G$3:$G$27) -> 0 | V8: =SUMIF($A$3:$A$27,CONCATENATE("*",N8,"*"),$H$3:$H$27) -> 0 | W8: =SUMIF($A$3:$A$27,CONCATENATE("*",N8,"*"),$J$3:$J$27) -> 1 | Y8: 1
A9: Stx1d | F9: 1 | J9: 1 | N9: Stx2e | O9: =SUMIF($A$3:$A$27,CONCATENATE("*",N9,"*"),$B$3:$B$27) -> 0 | P9: =SUMIF($A$3:$A$27,CONCATENATE("*",N9,"*"),$C$3:$C$27) -> 0 | Q9: =SUMIF($A$3:$A$27,CONCATENATE("*",N9,"*"),$D$3:$D$27) -> 0 | R9: =SUMIF($A$3:$A$27,CONCATENATE("*",N9,"*"),$E$3:$E$27) -> 8 | T9: =SUMIF($A$3:$A$27,CONCATENATE("*",N9,"*"),$F$3:$F$27) -> 0 | U9: =SUMIF($A$3:$A$27,CONCATENATE("*",N9,"*"),$G$3:$G$27) -> 0 | V9: =SUMIF($A$3:$A$27,CONCATENATE("*",N9,"*"),$H$3:$H$27) -> 0 | W9: =SUMIF($A$3:$A$27,CONCATENATE("*",N9,"*"),$J$3:$J$27) -> 8 | Y9: 8
A10: Stx2a | B10: 2 | D10: 22 | E10: 46 | F10: 10 | H10: 2 | J10: 82 | N10: Stx2g | O10: =SUMIF($A$3:$A$27,CONCATENATE("*",N10,"*"),$B$3:$B$27) -> 0 | P10: =SUMIF($A$3:$A$27,CONCATENATE("*",N10,"*"),$C$3:$C$27) -> 0 | Q10: =SUMIF($A$3:$A$27,CONCATENATE("*",N10,"*"),$D$3:$D$27) -> 0 | R10: =SUMIF($A$3:$A$27,CONCATENATE("*",N10,"*"),$E$3:$E$27) -> 2 | T10: =SUMIF($A$3:$A$27,CONCATENATE("*",N10,"*"),$F$3:$F$27) -> 0 | U10: =SUMIF($A$3:$A$27,CONCATENATE("*",N10,"*"),$G$3:$G$27) -> 0 | V10: =SUMIF($A$3:$A$27,CONCATENATE("*",N10,"*"),$H$3:$H$27) -> 0 | W10: =SUMIF($A$3:$A$27,CONCATENATE("*",N10,"*"),$J$3:$J$27) -> 2 | Y10: 2
A11: Stx2a,Stx1a | B11: 1 | C11: 2 | D11: 1 | E11: 68 | F11: 3 | G11: 1 | H11: 1 | J11: 77 | N11: Stx2i | O11: =SUMIF($A$3:$A$27,CONCATENATE("*",N11,"*"),$B$3:$B$27) -> 0 | P11: =SUMIF($A$3:$A$27,CONCATENATE("*",N11,"*"),$C$3:$C$27) -> 0 | Q11: =SUMIF($A$3:$A$27,CONCATENATE("*",N11,"*"),$D$3:$D$27) -> 0 | R11: =SUMIF($A$3:$A$27,CONCATENATE("*",N11,"*"),$E$3:$E$27) -> 12 | T11: =SUMIF($A$3:$A$27,CONCATENATE("*",N11,"*"),$F$3:$F$27) -> 0 | U11: =SUMIF($A$3:$A$27,CONCATENATE("*",N11,"*"),$G$3:$G$27) -> 0 | V11: =SUMIF($A$3:$A$27,CONCATENATE("*",N11,"*"),$H$3:$H$27) -> 0 | W11: =SUMIF($A$3:$A$27,CONCATENATE("*",N11,"*"),$J$3:$J$27) -> 12 | Y11: 12
A12: Stx2a,Stx2b,Stx1c | E12: 1 | J12: 1 | N12: Stx1d | O12: =SUMIF($A$3:$A$27,CONCATENATE("*",N12,"*"),$B$3:$B$27) -> 0 | P12: =SUMIF($A$3:$A$27,CONCATENATE("*",N12,"*"),$C$3:$C$27) -> 0 | Q12: =SUMIF($A$3:$A$27,CONCATENATE("*",N12,"*"),$D$3:$D$27) -> 0 | R12: =SUMIF($A$3:$A$27,CONCATENATE("*",N12,"*"),$E$3:$E$27) -> 0 | T12: =SUMIF($A$3:$A$27,CONCATENATE("*",N12,"*"),$F$3:$F$27) -> 1 | U12: =SUMIF($A$3:$A$27,CONCATENATE("*",N12,"*"),$G$3:$G$27) -> 0 | V12: =SUMIF($A$3:$A$27,CONCATENATE("*",N12,"*"),$H$3:$H$27) -> 0 | W12: =SUMIF($A$3:$A$27,CONCATENATE("*",N12,"*"),$J$3:$J$27) -> 1 | Y12: 1
A13: Stx2b | E13: 11 | J13: 11 | N13: Stx2h | O13: =SUMIF($A$3:$A$27,CONCATENATE("*",N13,"*"),$B$3:$B$27) -> 0 | P13: =SUMIF($A$3:$A$27,CONCATENATE("*",N13,"*"),$C$3:$C$27) -> 0 | Q13: =SUMIF($A$3:$A$27,CONCATENATE("*",N13,"*"),$D$3:$D$27) -> 0 | R13: =SUMIF($A$3:$A$27,CONCATENATE("*",N13,"*"),$E$3:$E$27) -> 0 | T13: =SUMIF($A$3:$A$27,CONCATENATE("*",N13,"*"),$F$3:$F$27) -> 0 | U13: =SUMIF($A$3:$A$27,CONCATENATE("*",N13,"*"),$G$3:$G$27) -> 0 | V13: =SUMIF($A$3:$A$27,CONCATENATE("*",N13,"*"),$H$3:$H$27) -> 1 | W13: =SUMIF($A$3:$A$27,CONCATENATE("*",N13,"*"),$J$3:$J$27) -> 1 | Y13: 1
A14: Stx2b,Stx1a | E14: 28 | J14: 28 | N14: Stx2j | O14: =SUMIF($A$3:$A$27,CONCATENATE("*",N14,"*"),$B$3:$B$27) -> 0 | P14: =SUMIF($A$3:$A$27,CONCATENATE("*",N14,"*"),$C$3:$C$27) -> 0 | Q14: =SUMIF($A$3:$A$27,CONCATENATE("*",N14,"*"),$D$3:$D$27) -> 0 | R14: =SUMIF($A$3:$A$27,CONCATENATE("*",N14,"*"),$E$3:$E$27) -> 0 | T14: =SUMIF($A$3:$A$27,CONCATENATE("*",N14,"*"),$F$3:$F$27) -> 0 | U14: =SUMIF($A$3:$A$27,CONCATENATE("*",N14,"*"),$G$3:$G$27) -> 0 | V14: =SUMIF($A$3:$A$27,CONCATENATE("*",N14,"*"),$H$3:$H$27) -> 1 | W14: =SUMIF($A$3:$A$27,CONCATENATE("*",N14,"*"),$J$3:$J$27) -> 1 | Y14: 1
A15: Stx2b,Stx1c | E15: 43 | J15: 43
A16: Stx2b,Stx2b | E16: 1 | J16: 1
A17: Stx2c | C17: 6 | D17: 1 | E17: 38 | F17: 3 | J17: 48 | N17: Stx Protein | O17: Dairy | P17: Environment | Q17: Flour | R17: Meat | S17: Nuts/Seeds | T17: Other | U17: Vegetable
A18: Stx2c,Stx1a | C18: 1 | E18: 6 | J18: 7 | N18: Stx1a | O18: 8 | P18: 3 | Q18: 5 | R18: 204 | S18: 4 | T18: 1 | U18: 2
A19: Stx2c,Stx2b | E19: 1 | J19: 1 | N19: Stx2a | O19: 10 | P19: 2 | Q19: 23 | R19: 176 | S19: 14 | T19: 1 | U19: 4
A20: Stx2d | B20: 3 | E20: 13 | J20: 16 | N20: Stx2d | O20: 3 | P20: - | Q20: - | R20: 15 | S20: - | T20: - | U20: -
A21: Stx2d,Stx1a | E21: 2 | J21: 2 | N21: Stx2c | O21: - | P21: 7 | Q21: 1 | R21: 52 | S21: 3 | T21: - | U21: -
A22: Stx2e | E22: 8 | J22: 8 | N22: Stx1c | O22: - | P22: - | Q22: 1 | R22: 80 | S22: - | T22: - | U22: -
A23: Stx2g | E23: 2 | J23: 2 | N23: Stx2b | O23: - | P23: - | Q23: - | R23: 86 | S23: - | T23: - | U23: -
A24: Stx2h | H24: 1 | J24: 1 | N24: Stx2k | O24: - | P24: - | Q24: - | R24: 1 | S24: - | T24: - | U24: -
A25: Stx2i | E25: 12 | J25: 12 | N25: Stx2e | O25: - | P25: - | Q25: - | R25: 8 | S25: - | T25: - | U25: -
A26: Stx2j | H26: 1 | J26: 1 | N26: Stx2g | O26: - | P26: - | Q26: - | R26: 2 | S26: - | T26: - | U26: -
A27: Stx2k,Stx2a | E27: 1 | J27: 1 | N27: Stx2i | O27: - | P27: - | Q27: - | R27: 12 | S27: - | T27: - | U27: -
A28: (blank) | N28: Stx1d | O28: - | P28: - | Q28: - | R28: - | S28: 1 | T28: - | U28: -
A29: Grand Total | B29: 13 | C29: 9 | D29: 29 | E29: 421 | F29: 18 | G29: 1 | H29: 6 | J29: 497 | N29: Stx2h | O29: - | P29: - | Q29: - | R29: - | S29: - | T29: - | U29: 1
N30: Stx2j | O30: - | P30: - | Q30: - | R30: - | S30: - | T30: - | U30: 1

Sheet stx_pies_497
A1: x_axis | B1: radius | C1: number_seqs | D1: protein_y_name | E1: total_protein | F1: Source | G1: total_source | H1: value | I1: y_axis | J1: Facet | K1: x_axis2 | L1: radius2
A2: 5 | B2: 12 | C2: 497 | D2: Stx1a | E2: 227 | F2: Dairy | G2: 8 | H2: =G2/E2*100 -> 3.5242291 | I2: =E2/C2*100 -> 45.674044 | J2: Including O157 | K2: 5 | L2: 17
A3: 35 | B3: 12 | C3: 497 | D3: Stx2a | E3: 230 | F3: Dairy | G3: 10 | H3: =G3/E3*100 -> 4.3478261 | I3: =E3/C3*100 -> 46.277666 | J3: Including O157 | K3: =K2+35 -> 40 | L3: 17
A4: 60 | B4: 12 | C4: 497 | D4: Stx2d | E4: 18 | F4: Dairy | G4: 3 | H4: =G4/E4*100 -> 16.666667 | I4: =E4/C4*100 -> 3.6217304 | J4: Including O157 | K4: =K3+35 -> 75 | L4: 17
A5: 85 | B5: 12 | C5: 497 | D5: Stx2c | E5: 63 | F5: Dairy | G5: 0 | H5: =G5/E5*100 -> 0 | I5: =E5/C5*100 -> 12.676056 | J5: Including O157 | K5: =K4+35 -> 110 | L5: 17
A6: 110 | B6: 12 | C6: 497 | D6: Stx1c | E6: 81 | F6: Dairy | G6: 0 | H6: =G6/E6*100 -> 0 | I6: =E6/C6*100 -> 16.297787 | J6: Including O157 | K6: =K5+35 -> 145 | L6: 17
A7: 135 | B7: 12 | C7: 497 | D7: Stx2b | E7: 86 | F7: Dairy | G7: 0 | H7: =G7/E7*100 -> 0 | I7: =E7/C7*100 -> 17.303823 | J7: Including O157 | K7: =K6+35 -> 180 | L7: 17
A8: 160 | B8: 12 | C8: 497 | D8: Stx2k | E8: 1 | F8: Dairy | G8: 0 | H8: =G8/E8*100 -> 0 | I8: =E8/C8*100 -> 0.20120724 | J8: Including O157 | K8: =K7+35 -> 215 | L8: 17
A9: 185 | B9: 12 | C9: 497 | D9: Stx2e | E9: 8 | F9: Dairy | G9: 0 | H9: =G9/E9*100 -> 0 | I9: =E9/C9*100 -> 1.6096579 | J9: Including O157 | K9: =K8+35 -> 250 | L9: 17
A10: 210 | B10: 12 | C10: 497 | D10: Stx2g | E10: 2 | F10: Dairy | G10: 0 | H10: =G10/E10*100 -> 0 | I10: =E10/C10*100 -> 0.40241449 | J10: Including O157 | K10: =K9+35 -> 285 | L10: 17
A11: 235 | B11: 12 | C11: 497 | D11: Stx2i | E11: 12 | F11: Dairy | G11: 0 | H11: =G11/E11*100 -> 0 | I11: =E11/C11*100 -> 2.4144869 | J11: Including O157 | K11: =K10+35 -> 320 | L11: 17
A12: 260 | B12: 12 | C12: 497 | D12: Stx1d | E12: 1 | F12: Dairy | G12: 0 | H12: =G12/E12*100 -> 0 | I12: =E12/C12*100 -> 0.20120724 | J12: Including O157 | K12: =K11+35 -> 355 | L12: 17
A13: 285 | B13: 12 | C13: 497 | D13: Stx2h | E13: 1 | F13: Dairy | G13: 0 | H13: =G13/E13*100 -> 0 | I13: =E13/C13*100 -> 0.20120724 | J13: Including O157 | K13: =K12+35 -> 390 | L13: 17
A14: 310 | B14: 12 | C14: 497 | D14: Stx2j | E14: 1 | F14: Dairy | G14: 0 | H14: =G14/E14*100 -> 0 | I14: =E14/C14*100 -> 0.20120724 | J14: Including O157 | K14: =K13+35 -> 425 | L14: 17
A15: 5 | B15: 12 | C15: 497 | D15: Stx1a | E15: 227 | F15: Environment | G15: 3 | H15: =G15/E15*100 -> 1.3215859 | I15: =E15/C15*100 -> 45.674044 | J15: Including O157 | K15: 5 | L15: 17
A16: 35 | B16: 12 | C16: 497 | D16: Stx2a | E16: 230 | F16: Environment | G16: 2 | H16: =G16/E16*100 -> 0.86956522 | I16: =E16/C16*100 -> 46.277666 | J16: Including O157 | K16: 40 | L16: 17
A17: 60 | B17: 12 | C17: 497 | D17: Stx2d | E17: 18 | F17: Environment | G17: 0 | H17: =G17/E17*100 -> 0 | I17: =E17/C17*100 -> 3.6217304 | J17: Including O157 | K17: 75 | L17: 17
A18: 85 | B18: 12 | C18: 497 | D18: Stx2c | E18: 63 | F18: Environment | G18: 7 | H18: =G18/E18*100 -> 11.111111 | I18: =E18/C18*100 -> 12.676056 | J18: Including O157 | K18: 110 | L18: 17
A19: 110 | B19: 12 | C19: 497 | D19: Stx1c | E19: 81 | F19: Environment | G19: 0 | H19: =G19/E19*100 -> 0 | I19: =E19/C19*100 -> 16.297787 | J19: Including O157 | K19: 145 | L19: 17
A20: 135 | B20: 12 | C20: 497 | D20: Stx2b | E20: 86 | F20: Environment | G20: 0 | H20: =G20/E20*100 -> 0 | I20: =E20/C20*100 -> 17.303823 | J20: Including O157 | K20: 180 | L20: 17
A21: 160 | B21: 12 | C21: 497 | D21: Stx2k | E21: 1 | F21: Environment | G21: 0 | H21: =G21/E21*100 -> 0 | I21: =E21/C21*100 -> 0.20120724 | J21: Including O157 | K21: 215 | L21: 17
A22: 185 | B22: 12 | C22: 497 | D22: Stx2e | E22: 8 | F22: Environment | G22: 0 | H22: =G22/E22*100 -> 0 | I22: =E22/C22*100 -> 1.6096579 | J22: Including O157 | K22: 250 | L22: 17
A23: 210 | B23: 12 | C23: 497 | D23: Stx2g | E23: 2 | F23: Environment | G23: 0 | H23: =G23/E23*100 -> 0 | I23: =E23/C23*100 -> 0.40241449 | J23: Including O157 | K23: 285 | L23: 17
A24: 235 | B24: 12 | C24: 497 | D24: Stx2i | E24: 12 | F24: Environment | G24: 0 | H24: =G24/E24*100 -> 0 | I24: =E24/C24*100 -> 2.4144869 | J24: Including O157 | K24: 320 | L24: 17
A25: 260 | B25: 12 | C25: 497 | D25: Stx1d | E25: 1 | F25: Environment | G25: 0 | H25: =G25/E25*100 -> 0 | I25: =E25/C25*100 -> 0.20120724 | J25: Including O157 | K25: 355 | L25: 17
A26: 285 | B26: 12 | C26: 497 | D26: Stx2h | E26: 1 | F26: Environment | G26: 0 | H26: =G26/E26*100 -> 0 | I26: =E26/C26*100 -> 0.20120724 | J26: Including O157 | K26: 390 | L26: 17
... A92: 310 | B92: 12 | C92: 497 | D92: Stx2j | E92: 1 | F92: Vegetable | G92: 1 | H92: =G92/E92*100 -> 100 | I92: =E92/C92*100 -> 0.20120724 | J92: Including O157 | K92: 425 | L92: 17

Sheet Sheet14
A3: Count of Vtx | B3: Column Labels
A4: Row Labels | B4: Dairy | C4: Flour | D4: Lamb | E4: Meat | F4: Nuts/Seeds | G4: Other | H4: Vegetable | I4: (blank) | J4: Grand Total
A5: aggR | G5: 3 | J5: 3
A6: eae | G6: 1 | J6: 1
A7: ND | E7: 1 | G7: 7 | J7: 8
A8: stx1a, eae | G8: 11 | J8: 11
A9: stx1a, stx2a | G9: 1 | J9: 1
A10: stx1a, stx2a, eae | G10: 4 | J10: 4
A11: stx1a, stx2c,eae | G11: 1 | J11: 1
A12: stx1d | G12: 1 | J12: 1
A13: stx2a, aggR | G13: 1 | J13: 1
A14: stx2a, eae | G14: 2 | J14: 2
A15: stx2a, stx2d | G15: 1 | J15: 1
A16: stx2c,eae | G16: 1 | J16: 1
A17: stx2h | H17: 1 | J17: 1
A18: vtx1a | C18: 5 | E18: 37 | G18: 9 | J18: 51
A19: vtx1a,vtx2b | E19: 1 | J19: 1
A20: vtx1a,vtx2c | E20: 1 | J20: 1
A21: vtx1a;vtx1c;vtx2b | E21: 1 | J21: 1
A22: vtx1a;vtx2a | C22: 9 | E22: 40 | F22: 14 | G22: 50 | H22: 2 | J22: 115
A23: vtx1a;vtx2a (interrupted) | E23: 1 | J23: 1
A24: vtx1a;vtx2b | D24: 8 | E24: 17 | G24: 1 | J24: 26
A25: vtx1a;vtx2c | C25: 1 | E25: 2 | G25: 10 | J25: 13
A26: vtx1a;vtx2d | E26: 2 | J26: 2
A27: vtx1c | B27: 2 | D27: 13 | E27: 15 | G27: 8 | J27: 38
A28: vtx1c,vtx2b | E28: 2 | J28: 2
A29: vtx1c;vtx2a | G29: 1 | J29: 1
A30: vtx1c;vtx2a;vtx2b | E30: 1 | J30: 1
A31: vtx1c;vtx2b | D31: 15 | E31: 23 | G31: 8 | J31: 46
A32: vtx1d | F32: 1 | G32: 4 | J32: 5
A33: vtx2a | B33: 2 | C33: 19 | E33: 33 | F33: 9 | G33: 19 | H33: 4 | J33: 86
A34: vtx2a;vtx2c | G34: 1 | J34: 1
A35: vtx2a;vtx2k | E35: 1 | J35: 1
A36: vtx2b | E36: 12 | G36: 5 | J36: 17
A37: vtx2b;vtx2c | E37: 2 | J37: 2
A38: vtx2b;vtx2c;vtx2d | G38: 1 | J38: 1
A39: vtx2b;vtx2d | E39: 2 | J39: 2
A40: vtx2c | C40: 5 | E40: 35 | F40: 4 | G40: 6 | J40: 50
A41: vtx2d | E41: 12 | G41: 8 | J41: 20
A42: vtx2e | D42: 1 | E42: 7 | G42: 3 | J42: 11
...

Sheet alldata
A1: Isolate identifiers | B1: Strain | C1: Sample identifier | D1: SEQID | E1: REFSEQ | F1: NOTES | G1: VTEC | H1: terB-C | I1: TerGenes | J1: terKMA | K1: Source_HC list | L1: DB source | M1: Source1 | N1: Source2 | O1: Serotype_HC list | P1: Serotype details | Q1: GenSeekR | R1: Vtx | S1: StxDB_V1 | T1: MLST | U1: rMLST | V1: AMR2_ | W1: ROGA RDIMS | X1: BioSample | Y1: Assembly | Z1: NOTES | AA1: BioProject | AB1: SRA accession | AC1: SRA accession | AD1: Isolate | AE1: Create date | AF1: Location | AG1: WGS accession | AH1: AMR genotypes core | AI1: K-mer group | AJ1: Scientific name | AK1: Virulence genotypes | AL1: Stress genotypes | AM1: AMR genotypes | AN1: AMRFinderPlus version | AO1: PD Ref Gene Catalog version | AP1: AMRFinderPlus analysis type | AQ1: Collection date | AR1: N50 | AS1: Length | AT1: Contigs | AU1: Library layout | AV1: Species TaxID | AW1: Level | AX1: Method | AY1: TaxID | AZ1: WGS prefix | BA1: Isolation type | BB1: Food origin | BC1: SNP cluster | BD1: Min-same | BE1: Min-diff
A2: CFIAFB20170161 | B2: CFIAFB20170161 | C2: GTA-FD-2017-MI-00044 | D2: 2017-SEQ-0168 | E2: 2017-SEQ-0168 | G2: YES | H2: - | I2: terZ/A/B/C/D/E/W | J2: terA (99.83%),terB 100.00%),terC (99.90%),terD 100.00%),terE 100.00%),terZ (99.83%) | K2: Flour | L2: Flour | M2: Flour | N2: =M2 -> Flour | O2: O121:H19 | P2: O121 (100.0):H19 (98.31) | Q2: eae;hlyAEc;O121;VT2;uidA | R2: vtx2a | S2: Stx2a_1_AB030484 | T2: 655 | U2: 1692 | V2: O121 (100.0):H19 (98.31) | W2: #N/A | X2: SAMN09468192 | Y2: GCA_012165175.1 | AA2: PRJNA454819 | AB2: SRS3464494 | AC2: SRR7435868 | AD2: PDT000336889.2 | AE2: 2018-06-26T21:05:42Z | AF2: Canada | AG2: DAAZCD000000000.1 | AH2: glpT_E448K=POINT,pmrB_Y358N=POINT | AI2: PDG000000004.5130 | AJ2: Escherichia coli | AK2: eae=COMPLETE,efa1=COMPLETE,ehxA=COMPLETE,espA=COMPLETE,espB=COMPLETE,espF=COMPLETE,espI=COMPLETE,espJ=COMPLETE,espK=COMPLETE,espP=COMPLETE,espX1=MISTRANSLATION,fdeC=COMPLETE,lpfA=COMPLETE,nleA=COMPLETE,nleB=COMPLETE,nleC=COMPLETE,nleC=PARTIAL_END_OF_CONTIG,sslE=HMM,stxA2c=COMPLETE,stxB2a=COMPLETE,tccP=PARTIAL,tir=COMPLETE,toxB=COMPLETE | AL2: ariR=COMPLETE,terD=COMPLETE,terW=COMPLETE,terZ=COMPLETE | AM2: acrF=COMPLETE,blaEC=COMPLETE,glpT_E448K=POINT,mdtM=COMPLETE,pmrB_Y358N=POINT | AN2: 3.11.26 | AO2: 2023-08-08.2 | AP2: COMBINED | AQ2: 2017 | AR2: 105664 | AS2: 5188081 | AT2: 227 | AU2: PAIRED | AV2: 562 | AW2: Contig | AX2: SKESA v. 2.2 | AY2: 562 | AZ2: DAAZCD | BA2: environmental/other | BC2: PDS000011681.24 | BD2: 3 | BE2: 3
A3: CFIAFB20170177 | B3: CFIAFB20170177 | C3: BUR-FI-2017-MI-00011 | D3: 2017-BUR-0001 | E3: 2017-BUR-0001 | G3: YES | H3: - | I3: terC | J3: 0 | K3: Other-Flour | L3: Other-Flour | M3: Flour | N3: =M3 -> Flour | O3: O8:H28 | P3: O8 (99.59):H28 (99.54) | Q3: VT2;hlyAEc;uidA | R3: vtx2a | S3: Stx2a_30_MZ229605O8:H28 | T3: 4496 | U3: 33427 | V3: #N/A | W3: #N/A | X3: SAMN09468183 | Y3: GCA_012164995.1 | AA3: PRJNA454819 | AB3: SRS3464489 | AC3: SRR7435865 | AD3: PDT000336886.2 | AE3: 2018-06-26T21:05:41Z | AF3: Canada | AG3: DAAZCB000000000.1 | AH3: glpT_E448K=POINT,pmrB_Y358N=POINT | AI3: PDG000000004.5130 | AJ3: Escherichia coli | AK3: ehxA=COMPLETE,espX1=COMPLETE,fdeC=COMPLETE,lpfA=COMPLETE,sslE=HMM,stxA2d=COMPLETE,stxB2e=COMPLETE | AL3: ariR=COMPLETE | AM3: acrF=COMPLETE,blaEC=COMPLETE,glpT_E448K=POINT,mdtM=COMPLETE,pmrB_Y358N=POINT | AN3: 3.11.26 | AO3: 2023-08-08.2 | AP3: COMBINED | AQ3: 2017 | AR3: 206403 | AS3: 4959509 | AT3: 57 | AU3: PAIRED | AV3: 562 | AW3: Contig | AX3: SKESA v. 2.2 | AY3: 562 | AZ3: DAAZCB | BA3: environmental/other | BC3: PDS000035329.15 | BD3: 0 | BE3: 27
